Workbook

Sheet 1. Start here
B1: Are the bills being read correctly?
B2: A check on how accurately the computer read our supplier bills
B4: What this is about
B5: We use a computer program (an AI) to read supplier bills and type up every part on them: the part number, the description and the price. Those typed-up lines feed the parts price reference. If the program misreads a part number or a price, the reference is wrong in a way nobody would notice.
B6: To check it, we asked a second, newer AI to read the same bills again, without showing it what the first one wrote. Where the two readings agree, the line is very likely right. Where they disagree, a person needs to look at the bill and decide.
B8: What we checked
B9: 45 bills, 474 part lines in total:
B10: • 30 bills picked at random (216 lines). These give a fair picture of how accurate the reading is overall.
B11: • 15 hand-picked bills (258 lines) that automatic checks had flagged as suspicious. These are for finding problems, so they are kept out of the overall accuracy figure.
B13: What we found so far
B14: Lines where both readings agree | C14: 209 of 216 random lines (96.8%) | D14: 453 of 474 across all bills (95.6%).
B15: Prices | C15: No differences | D15: Both readings gave the same price on every line we could compare. This is the most important result: prices drive the benchmark.
B16: Part numbers | C16: 13 lines differ | D16: 7 of them in the random bills. Often a single look-alike character (8 vs B, 1 vs I, 6 vs 0). These need a person to check (sheet 2).
B17: Items the second reading could not find | C17: 8 lines | D17: All on bill B32, a cropped screenshot. Some of its items may be cut off the image, and 3 look like the same item recorded twice.
B18: Other things to check | C18: 3 | D18: Bill numbers that differ, and items the first reading may have missed.
B19: Cost of the second reading | C19: US$1.74 | D19: One-off cost of re-reading all 45 bills.
B21: Important: agreement is good news, but it is not proof. Both AIs are made by the same company and can occasionally make the same mistake on a blurry character. That is why a person checks a small part of the work too (step 2 below).
B23: What we need from you (about 45–60 minutes)
B24: Step 1. Sheet "2. Please check these" (25 rows). For each row, click Open to see the bill, then pick an answer from the drop-down in the yellow column.
B25: Step 2. Sheet "3. Spot check" (34 lines on 5 bills). Type the part number and price you see on the bill. Do this before opening sheet 5, which shows the computers' answers.
B26: Step 3. Sheet "4. Results" fills itself in as you go. When steps 1 and 2 are done, it shows the final accuracy figures.
B28: Words used in this file
B29: First reading | C29: What the original program typed up when the bills were first added. This is what is in the parts price reference today.
B30: Second reading | C30: The new check: a newer AI (Claude Opus 5.5) reading the same bill again on its own.
B31: Part number | C31: The manufacturer's code printed on the bill that identifies the exact part (for example 52119-06971).
B32: Line / item | C32: One row on a bill: one part, with its quantity and price.
B33: Random / Hand-picked | C33: Random bills give a fair accuracy figure. Hand-picked bills were chosen because they looked suspicious, so they would make accuracy look worse than it is.
B34: Spaces and dashes | C34: Ignored when comparing part numbers. 52119-06971 and 52119 06971 count as the same.
B36: Source: PartsIndex_ocr_check_2026-10-15_opus55.xlsx · parts reference snapshot PIX-335e1802-6b06668c · bills in /home/jason/mm-parts-index/invoices
B38: Online look-ups done (15 Oct 2026): for each part-number disagreement on sheet 2, both readings were looked up in the maker's parts catalogue (Amayama for Kia, Mercedes-Benz, Honda and Toyota; web search for Tesla and Mazda). A real part number exists and matches the item; a misread usually does not. The finding and a suggested answer are in the last columns of sheet 2. Please still check the bill and pick the final answer yourself in the yellow column.

Sheet 2. Please check these
A1: No. | B1: Bill | C1: Random or hand-picked | D1: Open the bill | E1: What to check | F1: Item | G1: First reading | H1: Second reading | I1: How sure the second reading was | J1: Second reading's comment | K1: YOUR ANSWER (pick from list) | L1: If both are wrong, what is correct? | M1: Your notes | N1: _kind | O1: WHAT THE ONLINE LOOK-UP FOUND | P1: SUGGESTED ANSWER (please confirm) | Q1: Correct value suggested | R1: Look-up source
A2: 1 | B2: B01 | C2: Random | D2: Open | E2: The two readings give a different part number. Look at the bill and choose which is right. | F2: #4 CLIP | G2: KA14205 08 250B | H2: KA14206 08 250B | I2: Fairly sure | J2: Last character could be 'B' or '8'; read as 'B'. Unit price 2.30 x 6 PCS = 13.80. | N2: line | O2: First reading 14205-08250B does not exist in the Kia catalogue. Second reading 14206-08250B is a Kia CLIP (S$1). | P2: Second reading is right | R2: amayama.com
A3: 2 | B3: B01 | C3: Random | D3: Open | E3: The two readings give a different part number. Look at the bill and choose which is right. | F3: #5 STRIP-FR BUMPER | G3: KA66570 H8 400 | H3: KA86570 H8 400 | I3: Sure | N3: line | O3: First reading 66570-H8400 does not exist. Second reading 86570-H8400 is STRIP-FR BUMPER for Kia Rio / Stonic, matching the bill's description. | P3: Second reading is right | R3: amayama.com
A4: 3 | B4: B01 | C4: Random | D4: Open | E4: The two readings give a different part number. Look at the bill and choose which is right. | F4: #6 KA66311 H8 400/PANEL-FENDER,LH | G4: KA66311 H8 400 | H4: KA66311 H8 401 | I4: Sure | J4: Part No. column prints 'KA66311 H8 401', but the description text reads 'KA66311 H8 400/PANEL-FENDER,LH'. The two differ in the final digit. | N4: line | O4: Both numbers exist: 66311-H8400 and 66311-H8401 are both PANEL-FENDER, LH for Kia Rio / Stonic (two revisions of the same part). The second reading says the part-number column prints ...401 while the description text says ...400. Either way it is the same part, so the benchmark is not affected. | P4: Can't tell | R4: amayama.com
A5: 4 | B5: B01 | C5: Random | D5: Open | E5: The two readings give a different part number. Look at the bill and choose which is right. | F5: #10 GUARD ASSY-FRONT WHEEL,RH | G5: KAB6812 H8 400 | H5: KA86812 H8 400 | I5: Sure | N5: line | O5: First reading KAB6812 H8 400 has a letter B where a digit belongs. Second reading 86812-H8400 is GUARD ASSY-FRONT WHEEL, RH for Kia Rio / Stonic, matching the description. | P5: Second reading is right | R5: amayama.com
A6: 5 | B6: B03 | C6: Random | D6: Open | E6: The two readings give a different part number. Look at the bill and choose which is right. | F6: #3 FR LWR LAT | G6: 1244341-00-B | H6: 1044341-00-B | I6: Unsure | J6: The row is cut off at the bottom of the screenshot, so only the top half of the characters is visible. The part number and price are uncertain. Price may read SGD218.65 but cannot be confirmed. The description is also truncated (FR LWR LAT...). | N6: line | O6: 1044341-00 is Tesla Model 3's front lower lateral link (current revision -D), matching 'FR LWR LAT'. First reading 1244341 was not found. | P6: Second reading is right | R6: service.tesla.com
A7: 6 | B7: B11 | C7: Random | D7: Open | E7: The second reading found an item the first reading did not record. Should it have been recorded? Second reading right = yes, it was missed. First reading right = no, it does not belong. | F7: MOLDING MIDDLE G/UPPER (on page 2, separate invoice 8411268 dated 04/11/2025, not part of invoice 8410969) | G7: (not recorded) | H7: HD71152-T6A-901 · S$130 | N7: missed | O7: HD71152-T6A-901 is a real Honda part: MOLDING, MIDDLE GRILLE UPPER for the Honda Odyssey (S$177.68). The look-up cannot tell which invoice it belongs to; the second reading says it is on page 2 as a separate invoice (8411268). | P7: Can't tell | R7: amayama.com
A8: 7 | B8: B17 | C8: Random | D8: Open | E8: The two readings give a different part number. Look at the bill and choose which is right. | F8: #1 HEADLAMP LH (LED) | G8: GSKI-51-041A | H8: GSK1-51-041A | I8: Sure | J8: Pink highlighter mark crosses the part number but all characters remain legible. 'MZ 6 GL' printed below is a vehicle/model note, not part of the part number. Page 2 is a separate invoice (AR202508-09728 dated 23/08/2025, GRF5-51-075A PROTECTOR LH, qty 1, 50.00, subtotal 50.00). It is not listed as a missed line because it belongs to a different bill. | N8: line | O8: Neither GSKI-51-041A nor GSK1-51-041A is listed online (Mazda's '-51-041' means a headlamp). Mazda part-number prefixes use the digit 1 in this position (e.g. BHN2, EH47, KR22), so GSK1 is the likelier reading. Not confirmed. | P8: Second reading is right | R8: coxmazdaparts.com
A9: 8 | B9: B18 | C9: Random | D9: Open | E9: The two readings give a different part number. Look at the bill and choose which is right. | F9: #1 BRACKET | G9: 1 MBA205 620 34 01 | H9: MBA205 620 34 01 | I9: Sure | J9: Printed as '1 MBA205 620 34 01' in the PART NO. column. The leading '1' appears to be the line or item sequence number and is excluded. A reviewer should confirm this. LOC 1E-7C. | N9: line | O9: A205 620 34 01 is BRACKET, LEFT for the Mercedes C-Class, matching the description. The leading '1' in the first reading is the quantity column read into the part number. | P9: Second reading is right | R9: amayama.com
A10: 9 | B10: B21 | C10: Random | D10: Open | E10: The two readings give a different bill number. Look at the bill and choose which is right. | F10: Bill number | G10: LL10325981 | H10: LI10325981 | N10: header | O10: Not checked online: bill numbers are not in any parts catalogue.
A11: 10 | B11: B22 | C11: Random | D11: Open | E11: The two readings give a different bill number. Look at the bill and choose which is right. | F11: Bill number | G11: EPC-5199563-1 | H11: 5199563 | N11: header | O11: Not checked online: bill numbers are not in any parts catalogue.
A12: 11 | B12: B31 | C12: Hand-picked | D12: Open | E12: The two readings give a different part number. Look at the bill and choose which is right. | F12: #1 TIE ROD OUTER ASSY, EA | G12: 1044341-00-E | H12: 1044841-00-E | I12: Sure | N12: line | O12: The first reading (1044341-00-E) is the number of the front lower lateral link, a different part. The second reading 1044841-00-E is the outer tie rod for Model 3 / Y, matching 'TIE ROD OUTER ASSY'. | P12: Second reading is right | R12: evannex.com
A13: 12 | B13: B31 | C13: Hand-picked | D13: Open | E13: Both readings agree, but this part of the bill is hard to read. Please confirm the part number. | F13: #7 ASSEMBLY - FENDER SUPPORT - LEFT HAND | G13: 1771986-SC-C | H13: 1771986-SC-C | I13: Unsure | J13: The part number is heavily obscured by scan noise. Several digits and the final letter are guesses, roughly '17?19?6-SC-?'. The unit price is also obscured; it was taken from the clear line total of 24.82 at qty 1. | N13: line | O13: Both readings say 1771986-SC-C, which does not exist. The left fender support bracket for Model 3 is 1771936-SC-C (right-hand version 1771937), same description and the same S$24.82 price on other bills. So both readings misread a 3 as a 9. | P13: Both are wrong | Q13: 1771936-SC-C | R13: service.tesla.com
A14: 13 | B14: B31 | C14: Hand-picked | D14: Open | E14: The two readings give a different part number. Look at the bill and choose which is right. | F14: #8 FRT WHEELLINER ASSY, LH | G14: 1894553-00-E | H14: 1504553-00-E | I14: Unsure | J14: The first digits of the part number are obscured by noise; the second and third characters ('50') are a guess. The rest, '4553-00-E', is legible. | N14: line | O14: Neither 1894553-00-E nor 1504553-00-E was found online. Another Tesla bill in this check (B32) records the same item 'FRT WHEEL LINER ASSY, LH' at the same price (S$106.73) as 1694553-00-E, so both readings here may be wrong. Check the bill. | P14: Can't tell | R14: service.tesla.com
A15: 14 | B15: B31 | C15: Hand-picked | D15: Open | E15: The two readings give a different part number. Look at the bill and choose which is right. | F15: #15 FRONT FASCIA BASE UNPAINTED | G15: 1894314-SC-G | H15: 1694314-SC-G | I15: Fairly sure | J15: The second digit could be '6' or '0'. 'SC' is as printed. | N15: line | O15: Neither 1894314-SC-G nor 1694314-SC-G was found online. Check the bill. | P15: Can't tell
A16: 15 | B16: B32 | C16: Hand-picked | D16: Open | E16: The second reading could not find this item on the bill. Is it really on the bill? First reading right = it is there. Second reading right = it is not there. | F16: #1 FR LWR COMP LINK ASSY, LH | G16: 1344354-00-A · S$212.65 | H16: (not found on the bill) | I16: Unsure | J16: Not visible in this screenshot. The order list is scrolled and earlier rows are cut off above, so this row may be on another screenshot. | N16: line | O16: Not checked online: the question is whether the item is on the bill image, which a catalogue cannot answer.
A17: 16 | B17: B32 | C17: Hand-picked | D17: Open | E17: The second reading could not find this item on the bill. Is it really on the bill? First reading right = it is there. Second reading right = it is not there. | F17: #2 NON-DRIVEN HUB, 147mm FLANGE OD | G17: 1044126-00-C · S$233.64 | H17: (not found on the bill) | I17: Unsure | J17: Not visible in this screenshot. The order list is scrolled and earlier rows are cut off above. | N17: line | O17: Not checked online: the question is whether the item is on the bill image, which a catalogue cannot answer.
A18: 17 | B18: B32 | C18: Hand-picked | D18: Open | E18: The second reading could not find this item on the bill. Is it really on the bill? First reading right = it is there. Second reading right = it is not there. | F18: #3 18" GLIDER WHEEL COVER, MODEL 3 | G18: 1344231-00-C · S$60.19 | H18: (not found on the bill) | I18: Unsure | J18: Not visible in this screenshot. The order list is scrolled and earlier rows are cut off above. | N18: line | O18: Not checked online: the question is whether the item is on the bill image, which a catalogue cannot answer.
A19: 18 | B19: B32 | C19: Hand-picked | D19: Open | E19: The second reading could not find this item on the bill. Is it really on the bill? First reading right = it is there. Second reading right = it is not there. | F19: #4 WHEEL, 18X8.5J ET38, GLIDER | G19: 1344221-00-B · S$455.09 | H19: (not found on the bill) | I19: Unsure | J19: Not visible in this screenshot. The order list is scrolled and earlier rows are cut off above. | N19: line | O19: Not checked online: the question is whether the item is on the bill image, which a catalogue cannot answer.
A20: 19 | B20: B32 | C20: Hand-picked | D20: Open | E20: The second reading could not find this item on the bill. Is it really on the bill? First reading right = it is there. Second reading right = it is not there. | F20: #5 ASSEMBLY - FENDER SUPPORT - LEFT HAND | G20: 1771936-SC-C · S$24.82 | H20: (not found on the bill) | I20: Unsure | J20: Only the fragment 'LEFT HAND' is visible at the top edge, possibly the end of this description. The part number and price are cut off and cannot be verified. | N20: line | O20: Not checked online: the question is whether the item is on the bill image, which a catalogue cannot answer.
A21: 20 | B21: B32 | C21: Hand-picked | D21: Open | E21: The second reading could not find this item on the bill. Is it really on the bill? First reading right = it is there. Second reading right = it is not there. | F21: #9 FRT WHEEL LINER ASSY, LH | G21: 1694553-00-E · S$106.73 | H21: (not found on the bill) | I21: Sure | J21: Duplicate of line 6. Only one such row appears on the document, likely double-counted from overlapping screenshots. | N21: line | O21: Not checked online: the question is whether the item is on the bill image, which a catalogue cannot answer.
A22: 21 | B22: B32 | C22: Hand-picked | D22: Open | E22: The second reading could not find this item on the bill. Is it really on the bill? First reading right = it is there. Second reading right = it is not there. | F22: #10 ASSEMBLY - FENDER - LEFT HAND | G22: 1714884-EC-D · S$436.29 | H22: (not found on the bill) | I22: Sure | J22: Duplicate of line 7. Only one such row appears on the document, likely double-counted from overlapping screenshots. | N22: line | O22: Not checked online: the question is whether the item is on the bill image, which a catalogue cannot answer.
A23: 22 | B23: B32 | C23: Hand-picked | D23: Open | E23: The second reading could not find this item on the bill. Is it really on the bill? First reading right = it is there. Second reading right = it is not there. | F23: #11 HEADLAMP ASY ECE, LH | G23: 1760888-00-F · S$1741 | H23: (not found on the bill) | I23: Sure | J23: Duplicate of line 8. Only one such row appears on the document, likely double-counted from overlapping screenshots. | N23: line | O23: Not checked online: the question is whether the item is on the bill image, which a catalogue cannot answer.
A24: 23 | B24: B34 | C24: Hand-picked | D24: Open | E24: The two readings give a different part number. Look at the bill and choose which is right. | F24: #15 RAD FAN COWLING 10" | G24: 16711-30082 | H24: T16711-30082 | I24: Fairly sure | J24: A handwritten tick mark overlaps the first character. It reads like 'I6711' and is taken as 'T' to be consistent with the other T-prefixed stock IDs. Verify. | N24: line | O24: Both readings are the same Toyota part: 16711-30082 is SHROUD, FAN for the Hiace (S$103.50). The second reading's leading 'T' is from a tick mark over the first character; the printed number has no prefix. The benchmark is not affected either way. | P24: First reading is right | R24: amayama.com
A25: 24 | B25: B42 | C25: Hand-picked | D25: Open | E25: The two readings give a different part number. Look at the bill and choose which is right. | F25: #2 HINGE BONNET LH | G25: MBA253 880 02 28 | H25: MBA253 880 01 28 | I25: Sure | N25: line | O25: First reading A253 880 02 28 is HINGE, RIGHT. Second reading A253 880 01 28 is HINGE, LEFT (both Mercedes GLC). The bill says 'HINGE BONNET LH', so the second reading matches. | P25: Second reading is right | R25: amayama.com
A26: 25 | B26: B44 | C26: Hand-picked | D26: Open | E26: The two readings give a different part number. Look at the bill and choose which is right. | F26: #56 FR.CRASH SENSOR(R&L) | G26: H77930-T7A-J01 | H26: H77930-T5A-J01 | I26: Sure | N26: line | O26: Second reading 77930-T5A-J01 is SENSOR ASSY, FR. CRASH (Honda Fit / Jazz / HR-V / City and others). First reading 77930-T7A-J01 is not listed anywhere (T7A-C11 exists for the HR-V, but not -J01). | P26: Second reading is right | R26: amayama.com

Sheet 3. Spot check
A1: Type what you see on the bill. Please don't look at sheet 5 first: seeing the computers' answers makes it easy to agree with them by mistake.
A2: Bill | B2: Item no. | C2: Description | D2: Qty | E2: Line total (S$) | F2: Open the bill | G2: TYPE the part number you see | H2: TYPE the unit price you see (S$) | I2: Matches second reading? (part no.) | J2: Matches second reading? (price) | K2: Matches first reading? (part no.) | L2: Matches first reading? (price) | M2: _2nd pn | N2: _2nd unit | O2: _1st pn | P2: _1st unit
A3: B04 | B3: 1 | C3: RADIATOR | D3: 1 | E3: 3853 | F3: Open | I3: =IF(OR(G3="",M3=""),"",IF(UPPER(SUBSTITUTE(SUBSTITUTE(SUBSTITUTE(SUBSTITUTE(G3," ",""),"-",""),".",""),"/",""))=UPPER(SUBSTITUTE(SUBSTITUTE(SUBSTITUTE(SUBSTITUTE(M3," ",""),"-",""),".",""),"/","")),"Yes","No")) | J3: =IF(OR(H3="",N3=""),"",IF(ABS(H3-N3)<=0.01,"Yes","No")) | K3: =IF(OR(G3="",O3=""),"",IF(UPPER(SUBSTITUTE(SUBSTITUTE(SUBSTITUTE(SUBSTITUTE(G3," ",""),"-",""),".",""),"/",""))=UPPER(SUBSTITUTE(SUBSTITUTE(SUBSTITUTE(SUBSTITUTE(O3," ",""),"-",""),".",""),"/","")),"Yes","No")) | L3: =IF(OR(H3="",P3=""),"",IF(ABS(H3-P3)<=0.01,"Yes","No")) | M3: 1769999 | N3: 3853 | O3: 1769999 | P3: 3853
A4: B04 | B4: 2 | C4: FRAME | D4: 1 | E4: 2825 | F4: Open | I4: =IF(OR(G4="",M4=""),"",IF(UPPER(SUBSTITUTE(SUBSTITUTE(SUBSTITUTE(SUBSTITUTE(G4," ",""),"-",""),".",""),"/",""))=UPPER(SUBSTITUTE(SUBSTITUTE(SUBSTITUTE(SUBSTITUTE(M4," ",""),"-",""),".",""),"/","")),"Yes","No")) | J4: =IF(OR(H4="",N4=""),"",IF(ABS(H4-N4)<=0.01,"Yes","No")) | K4: =IF(OR(G4="",O4=""),"",IF(UPPER(SUBSTITUTE(SUBSTITUTE(SUBSTITUTE(SUBSTITUTE(G4," ",""),"-",""),".",""),"/",""))=UPPER(SUBSTITUTE(SUBSTITUTE(SUBSTITUTE(SUBSTITUTE(O4," ",""),"-",""),".",""),"/","")),"Yes","No")) | L4: =IF(OR(H4="",P4=""),"",IF(ABS(H4-P4)<=0.01,"Yes","No")) | M4: 2121771 | N4: 2825 | O4: 2121771 | P4: 2825
A5: B04 | B5: 3 | C5: CHARGE AIR COOLER | D5: 1 | E5: 4670 | F5: Open | I5: =IF(OR(G5="",M5=""),"",IF(UPPER(SUBSTITUTE(SUBSTITUTE(SUBSTITUTE(SUBSTITUTE(G5," ",""),"-",""),".",""),"/",""))=UPPER(SUBSTITUTE(SUBSTITUTE(SUBSTITUTE(SUBSTITUTE(M5," ",""),"-",""),".",""),"/","")),"Yes","No")) | J5: =IF(OR(H5="",N5=""),"",IF(ABS(H5-N5)<=0.01,"Yes","No")) | K5: =IF(OR(G5="",O5=""),"",IF(UPPER(SUBSTITUTE(SUBSTITUTE(SUBSTITUTE(SUBSTITUTE(G5," ",""),"-",""),".",""),"/",""))=UPPER(SUBSTITUTE(SUBSTITUTE(SUBSTITUTE(SUBSTITUTE(O5," ",""),"-",""),".",""),"/","")),"Yes","No")) | L5: =IF(OR(H5="",P5=""),"",IF(ABS(H5-P5)<=0.01,"Yes","No")) | M5: 1871265 | N5: 4670 | O5: 1871265 | P5: 4670
A6: B04 | B6: 4 | C6: FAN COVER | D6: 1 | E6: 1358 | F6: Open | I6: =IF(OR(G6="",M6=""),"",IF(UPPER(SUBSTITUTE(SUBSTITUTE(SUBSTITUTE(SUBSTITUTE(G6," ",""),"-",""),".",""),"/",""))=UPPER(SUBSTITUTE(SUBSTITUTE(SUBSTITUTE(SUBSTITUTE(M6," ",""),"-",""),".",""),"/","")),"Yes","No")) | J6: =IF(OR(H6="",N6=""),"",IF(ABS(H6-N6)<=0.01,"Yes","No")) | K6: =IF(OR(G6="",O6=""),"",IF(UPPER(SUBSTITUTE(SUBSTITUTE(SUBSTITUTE(SUBSTITUTE(G6," ",""),"-",""),".",""),"/",""))=UPPER(SUBSTITUTE(SUBSTITUTE(SUBSTITUTE(SUBSTITUTE(O6," ",""),"-",""),".",""),"/","")),"Yes","No")) | L6: =IF(OR(H6="",P6=""),"",IF(ABS(H6-P6)<=0.01,"Yes","No")) | M6: 2004491 | N6: 1358 | O6: 2004491 | P6: 1358
A7: B04 | B7: 5 | C7: HOSE | D7: 1 | E7: 224 | F7: Open | I7: =IF(OR(G7="",M7=""),"",IF(UPPER(SUBSTITUTE(SUBSTITUTE(SUBSTITUTE(SUBSTITUTE(G7," ",""),"-",""),".",""),"/",""))=UPPER(SUBSTITUTE(SUBSTITUTE(SUBSTITUTE(SUBSTITUTE(M7," ",""),"-",""),".",""),"/","")),"Yes","No")) | J7: =IF(OR(H7="",N7=""),"",IF(ABS(H7-N7)<=0.01,"Yes","No")) | K7: =IF(OR(G7="",O7=""),"",IF(UPPER(SUBSTITUTE(SUBSTITUTE(SUBSTITUTE(SUBSTITUTE(G7," ",""),"-",""),".",""),"/",""))=UPPER(SUBSTITUTE(SUBSTITUTE(SUBSTITUTE(SUBSTITUTE(O7," ",""),"-",""),".",""),"/","")),"Yes","No")) | L7: =IF(OR(H7="",P7=""),"",IF(ABS(H7-P7)<=0.01,"Yes","No")) | M7: 2064249 | N7: 224 | O7: 2064249 | P7: 224
A8: B04 | B8: 6 | C8: VIBRATION INSULATOR | D8: 4 | E8: 514 | F8: Open | I8: =IF(OR(G8="",M8=""),"",IF(UPPER(SUBSTITUTE(SUBSTITUTE(SUBSTITUTE(SUBSTITUTE(G8," ",""),"-",""),".",""),"/",""))=UPPER(SUBSTITUTE(SUBSTITUTE(SUBSTITUTE(SUBSTITUTE(M8," ",""),"-",""),".",""),"/","")),"Yes","No")) | J8: =IF(OR(H8="",N8=""),"",IF(ABS(H8-N8)<=0.01,"Yes","No")) | K8: =IF(OR(G8="",O8=""),"",IF(UPPER(SUBSTITUTE(SUBSTITUTE(SUBSTITUTE(SUBSTITUTE(G8," ",""),"-",""),".",""),"/",""))=UPPER(SUBSTITUTE(SUBSTITUTE(SUBSTITUTE(SUBSTITUTE(O8," ",""),"-",""),".",""),"/","")),"Yes","No")) | L8: =IF(OR(H8="",P8=""),"",IF(ABS(H8-P8)<=0.01,"Yes","No")) | M8: 1363634 | N8: 128.5 | O8: 1363634 | P8: 128.5
A9: B04 | B9: 7 | C9: FRAME | D9: 1 | E9: 3395 | F9: Open | I9: =IF(OR(G9="",M9=""),"",IF(UPPER(SUBSTITUTE(SUBSTITUTE(SUBSTITUTE(SUBSTITUTE(G9," ",""),"-",""),".",""),"/",""))=UPPER(SUBSTITUTE(SUBSTITUTE(SUBSTITUTE(SUBSTITUTE(M9," ",""),"-",""),".",""),"/","")),"Yes","No")) | J9: =IF(OR(H9="",N9=""),"",IF(ABS(H9-N9)<=0.01,"Yes","No")) | K9: =IF(OR(G9="",O9=""),"",IF(UPPER(SUBSTITUTE(SUBSTITUTE(SUBSTITUTE(SUBSTITUTE(G9," ",""),"-",""),".",""),"/",""))=UPPER(SUBSTITUTE(SUBSTITUTE(SUBSTITUTE(SUBSTITUTE(O9," ",""),"-",""),".",""),"/","")),"Yes","No")) | L9: =IF(OR(H9="",P9=""),"",IF(ABS(H9-P9)<=0.01,"Yes","No")) | M9: 2188551 | N9: 3395 | O9: 2188551 | P9: 3395
A10: B04 | B10: 8 | C10: FLANGE SCREW | D10: 12 | E10: 36 | F10: Open | I10: =IF(OR(G10="",M10=""),"",IF(UPPER(SUBSTITUTE(SUBSTITUTE(SUBSTITUTE(SUBSTITUTE(G10," ",""),"-",""),".",""),"/",""))=UPPER(SUBSTITUTE(SUBSTITUTE(SUBSTITUTE(SUBSTITUTE(M10," ",""),"-",""),".",""),"/","")),"Yes","No")) | J10: =IF(OR(H10="",N10=""),"",IF(ABS(H10-N10)<=0.01,"Yes","No")) | K10: =IF(OR(G10="",O10=""),"",IF(UPPER(SUBSTITUTE(SUBSTITUTE(SUBSTITUTE(SUBSTITUTE(G10," ",""),"-",""),".",""),"/",""))=UPPER(SUBSTITUTE(SUBSTITUTE(SUBSTITUTE(SUBSTITUTE(O10," ",""),"-",""),".",""),"/","")),"Yes","No")) | L10: =IF(OR(H10="",P10=""),"",IF(ABS(H10-P10)<=0.01,"Yes","No")) | M10: 0812516 | N10: 3 | O10: 0812516 | P10: 3
A11: B04 | B11: 9 | C11: COOLING PACKAGE | D11: 1 | E11: 1240 | F11: Open | I11: =IF(OR(G11="",M11=""),"",IF(UPPER(SUBSTITUTE(SUBSTITUTE(SUBSTITUTE(SUBSTITUTE(G11," ",""),"-",""),".",""),"/",""))=UPPER(SUBSTITUTE(SUBSTITUTE(SUBSTITUTE(SUBSTITUTE(M11," ",""),"-",""),".",""),"/","")),"Yes","No")) | J11: =IF(OR(H11="",N11=""),"",IF(ABS(H11-N11)<=0.01,"Yes","No")) | K11: =IF(OR(G11="",O11=""),"",IF(UPPER(SUBSTITUTE(SUBSTITUTE(SUBSTITUTE(SUBSTITUTE(G11," ",""),"-",""),".",""),"/",""))=UPPER(SUBSTITUTE(SUBSTITUTE(SUBSTITUTE(SUBSTITUTE(O11," ",""),"-",""),".",""),"/","")),"Yes","No")) | L11: =IF(OR(H11="",P11=""),"",IF(ABS(H11-P11)<=0.01,"Yes","No")) | M11: 2379981 | N11: 1240 | O11: 2379981 | P11: 1240
A12: B04 | B12: 10 | C12: FLANGE SCREW | D12: 4 | E12: 5.28 | F12: Open | I12: =IF(OR(G12="",M12=""),"",IF(UPPER(SUBSTITUTE(SUBSTITUTE(SUBSTITUTE(SUBSTITUTE(G12," ",""),"-",""),".",""),"/",""))=UPPER(SUBSTITUTE(SUBSTITUTE(SUBSTITUTE(SUBSTITUTE(M12," ",""),"-",""),".",""),"/","")),"Yes","No")) | J12: =IF(OR(H12="",N12=""),"",IF(ABS(H12-N12)<=0.01,"Yes","No")) | K12: =IF(OR(G12="",O12=""),"",IF(UPPER(SUBSTITUTE(SUBSTITUTE(SUBSTITUTE(SUBSTITUTE(G12," ",""),"-",""),".",""),"/",""))=UPPER(SUBSTITUTE(SUBSTITUTE(SUBSTITUTE(SUBSTITUTE(O12," ",""),"-",""),".",""),"/","")),"Yes","No")) | L12: =IF(OR(H12="",P12=""),"",IF(ABS(H12-P12)<=0.01,"Yes","No")) | M12: 0812519 | N12: 1.32 | O12: 0812519 | P12: 1.32
A13: B04 | B13: 11 | C13: BRACKET | D13: 1 | E13: 115 | F13: Open | I13: =IF(OR(G13="",M13=""),"",IF(UPPER(SUBSTITUTE(SUBSTITUTE(SUBSTITUTE(SUBSTITUTE(G13," ",""),"-",""),".",""),"/",""))=UPPER(SUBSTITUTE(SUBSTITUTE(SUBSTITUTE(SUBSTITUTE(M13," ",""),"-",""),".",""),"/","")),"Yes","No")) | J13: =IF(OR(H13="",N13=""),"",IF(ABS(H13-N13)<=0.01,"Yes","No")) | K13: =IF(OR(G13="",O13=""),"",IF(UPPER(SUBSTITUTE(SUBSTITUTE(SUBSTITUTE(SUBSTITUTE(G13," ",""),"-",""),".",""),"/",""))=UPPER(SUBSTITUTE(SUBSTITUTE(SUBSTITUTE(SUBSTITUTE(O13," ",""),"-",""),".",""),"/","")),"Yes","No")) | L13: =IF(OR(H13="",P13=""),"",IF(ABS(H13-P13)<=0.01,"Yes","No")) | M13: 2051971 | N13: 115 | O13: 2051971 | P13: 115
A14: B04 | B14: 12 | C14: WASHER | D14: 4 | E14: 18.4 | F14: Open | I14: =IF(OR(G14="",M14=""),"",IF(UPPER(SUBSTITUTE(SUBSTITUTE(SUBSTITUTE(SUBSTITUTE(G14," ",""),"-",""),".",""),"/",""))=UPPER(SUBSTITUTE(SUBSTITUTE(SUBSTITUTE(SUBSTITUTE(M14," ",""),"-",""),".",""),"/","")),"Yes","No")) | J14: =IF(OR(H14="",N14=""),"",IF(ABS(H14-N14)<=0.01,"Yes","No")) | K14: =IF(OR(G14="",O14=""),"",IF(UPPER(SUBSTITUTE(SUBSTITUTE(SUBSTITUTE(SUBSTITUTE(G14," ",""),"-",""),".",""),"/",""))=UPPER(SUBSTITUTE(SUBSTITUTE(SUBSTITUTE(SUBSTITUTE(O14," ",""),"-",""),".",""),"/","")),"Yes","No")) | L14: =IF(OR(H14="",P14=""),"",IF(ABS(H14-P14)<=0.01,"Yes","No")) | M14: 0394714 | N14: 4.6 | O14: 0394714 | P14: 4.6
... A36: B19 | B36: 3 | C36: NOZZLE-LAMP WASHER LH | D36: 1 | E36: 50 | F36: Open | I36: =IF(OR(G36="",M36=""),"",IF(UPPER(SUBSTITUTE(SUBSTITUTE(SUBSTITUTE(SUBSTITUTE(G36," ",""),"-",""),".",""),"/",""))=UPPER(SUBSTITUTE(SUBSTITUTE(SUBSTITUTE(SUBSTITUTE(M36," ",""),"-",""),".",""),"/","")),"Yes","No")) | J36: =IF(OR(H36="",N36=""),"",IF(ABS(H36-N36)<=0.01,"Yes","No")) | K36: =IF(OR(G36="",O36=""),"",IF(UPPER(SUBSTITUTE(SUBSTITUTE(SUBSTITUTE(SUBSTITUTE(G36," ",""),"-",""),".",""),"/",""))=UPPER(SUBSTITUTE(SUBSTITUTE(SUBSTITUTE(SUBSTITUTE(O36," ",""),"-",""),".",""),"/","")),"Yes","No")) | L36: =IF(OR(H36="",P36=""),"",IF(ABS(H36-P36)<=0.01,"Yes","No")) | M36: S86636-SJ110 | N36: 50 | O36: S86636-SJ110 | P36: 50

Sheet 4. Results
A1: Progress
A2: Rows answered on sheet 2 | B2: =COUNTA('2. Please check these'!$K$2:$K$26)&" of 25" | C2: Step 1
A3: Lines typed on sheet 3 | B3: =COUNTA('3. Spot check'!$G$3:$G$36)&" of 34" | C3: Step 2
A5: The answer: how accurate is the first reading?
A6: Mistakes found in the random bills | B6: =COUNTIFS('2. Please check these'!$C$2:$C$26,"Random",'2. Please check these'!$N$2:$N$26,"line",'2. Please check these'!$K$2:$K$26,"Second reading is right")+COUNTIFS('2. Please check these'!$C$2:$C$26,"Random",'2. Please check these'!$N$2:$N$26,"line",'2. Please check these'!$K$2:$K$26,"Both are wrong") | C6: Rows on sheet 2 from random bills where you answered "Second reading is right" or "Both are wrong".
A7: Lines read correctly (random bills) | B7: =IFERROR(1-(COUNTIFS('2. Please check these'!$C$2:$C$26,"Random",'2. Please check these'!$N$2:$N$26,"line",'2. Please check these'!$K$2:$K$26,"Second reading is right")+COUNTIFS('2. Please check these'!$C$2:$C$26,"Random",'2. Please check these'!$N$2:$N$26,"line",'2. Please check these'!$K$2:$K$26,"Both are wrong"))/216,"") | C7: Out of 216 random lines. This is the main figure to report, once sheet 2 is finished.
A8: In plain words | B8: =IF(COUNTA('2. Please check these'!$K$2:$K$26)<25,"Finish sheet 2 first","About "&TEXT((COUNTIFS('2. Please check these'!$C$2:$C$26,"Random",'2. Please check these'!$N$2:$N$26,"line",'2. Please check these'!$K$2:$K$26,"Second reading is right")+COUNTIFS('2. Please check these'!$C$2:$C$26,"Random",'2. Please check these'!$N$2:$N$26,"line",'2. Please check these'!$K$2:$K$26,"Both are wrong"))/216*100,"0.0")&" mistakes in every 100 lines")
A9: Items the first reading missed | B9: =COUNTIFS('2. Please check these'!$N$2:$N$26,"missed",'2. Please check these'!$K$2:$K$26,"Second reading is right") | C9: Items on a bill that never made it into the reference.
A10: Bill numbers read wrongly | B10: =COUNTIFS('2. Please check these'!$N$2:$N$26,"header",'2. Please check these'!$K$2:$K$26,"Second reading is right")+COUNTIFS('2. Please check these'!$N$2:$N$26,"header",'2. Please check these'!$K$2:$K$26,"Both are wrong")
A12: Can we trust the second reading? (from the spot check)
A13: Second reading wrong on part number | B13: =IFERROR(COUNTIF('3. Spot check'!$I$3:$I$36,"No")/(COUNTIF('3. Spot check'!$I$3:$I$36,"Yes")+COUNTIF('3. Spot check'!$I$3:$I$36,"No")),"") | C13: How often what you typed differs from the second reading. Should be close to 0%.
A14: Second reading wrong on price | B14: =IFERROR(COUNTIF('3. Spot check'!$J$3:$J$36,"No")/(COUNTIF('3. Spot check'!$J$3:$J$36,"Yes")+COUNTIF('3. Spot check'!$J$3:$J$36,"No")),"") | C14: Should be close to 0%.
A15: First reading wrong on part number | B15: =IFERROR(COUNTIF('3. Spot check'!$K$3:$K$36,"No")/(COUNTIF('3. Spot check'!$K$3:$K$36,"Yes")+COUNTIF('3. Spot check'!$K$3:$K$36,"No")),"") | C15: A small direct check of the first reading, as a cross-check on the main figure.
A16: First reading wrong on price | B16: =IFERROR(COUNTIF('3. Spot check'!$L$3:$L$36,"No")/(COUNTIF('3. Spot check'!$L$3:$L$36,"Yes")+COUNTIF('3. Spot check'!$L$3:$L$36,"No")),"")
A17: What it means | B17: =IF(COUNTA('3. Spot check'!$G$3:$G$36)=0,"Do the spot check first",IF(IFERROR(COUNTIF('3. Spot check'!$I$3:$I$36,"No")/(COUNTIF('3. Spot check'!$I$3:$I$36,"Yes")+COUNTIF('3. Spot check'!$I$3:$I$36,"No")),0)<=0.03,"The second reading is reliable, so agreement between the two readings can be trusted.","The second reading also makes mistakes. Treat agreement with caution and check more lines by hand."))

Sheet 5. All lines
A1: Every line we checked, with both readings side by side. Please finish the spot check (sheet 3) before looking here.
A2: Bill | B2: Random or hand-picked | C2: Item no. | D2: Description | E2: Part no. — first reading | F2: Part no. — second reading | G2: Price — first reading (S$) | H2: Price — second reading (S$) | I2: Result | J2: Open the bill
A3: B01 | B3: Random | C3: 1 | D3: LAMP ASSY-HEAD,LH | E3: KA92101 H8 510 | F3: KA92101 H8 510 | G3: 1100 | H3: 1100 | I3: Same | J3: Open
A4: B01 | B4: Random | C4: 2 | D4: LAMP ASSY-HEAD,RH | E4: KA92102 H8 510 | F4: KA92102 H8 510 | G4: 1100 | H4: 1100 | I4: Same | J4: Open
A5: B01 | B5: Random | C5: 3 | D5: COVER-RADIATOR GRILLE UPR | E5: KA86353 H8 400 | F5: KA86353 H8 400 | G5: 45 | H5: 45 | I5: Same | J5: Open
A6: B01 | B6: Random | C6: 4 | D6: CLIP | E6: KA14205 08 250B | F6: KA14206 08 250B | G6: 2.3 | H6: 2.3 | I6: Part no. differs | J6: Open
A7: B01 | B7: Random | C7: 5 | D7: STRIP-FR BUMPER | E7: KA66570 H8 400 | F7: KA86570 H8 400 | G7: 19 | H7: 19 | I7: Part no. differs | J7: Open
A8: B01 | B8: Random | C8: 6 | D8: KA66311 H8 400/PANEL-FENDER,LH | E8: KA66311 H8 400 | F8: KA66311 H8 401 | G8: 210 | H8: 210 | I8: Part no. differs | J8: Open
A9: B01 | B9: Random | C9: 7 | D9: PANEL-FENDER,RH | E9: KA66321 H8 401 | F9: KA66321 H8 401 | G9: 210 | H9: 210 | I9: Same | J9: Open
A10: B01 | B10: Random | C10: 8 | D10: GARNISH ASSY-FNDR SIDE,LH | E10: KA87711 H8 400 | F10: KA87711 H8 400 | G10: 35 | H10: 35 | I10: Same | J10: Open
A11: B01 | B11: Random | C11: 9 | D11: GARNISH ASSY-FNDR SIDE,RH | E11: KA87712 H8 400 | F11: KA87712 H8 400 | G11: 35 | H11: 35 | I11: Same | J11: Open
A12: B01 | B12: Random | C12: 10 | D12: GUARD ASSY-FRONT WHEEL,RH | E12: KAB6812 H8 400 | F12: KA86812 H8 400 | G12: 40 | H12: 40 | I12: Part no. differs | J12: Open
A13: B02 | B13: Random | C13: 1 | D13: FRT HEAD LAMP LH 14" ( ASSY ) 2.0 | E13: N26060-4EA0B | F13: N26060-4EA0B | G13: 1480 | H13: 1480 | I13: Same | J13: Open
A14: B03 | B14: Random | C14: 1 | D14: FRONT T-BADGE, SATIN CHROMING | E14: 1694511-00-C | F14: 1694511-00-C | G14: 41.38 | H14: 41.38 | I14: Same | J14: Open
... A80: B11 | B80: Random | C80: 6 | D80: MOLDING R MIDDLE G/LOWER | E80: HD71154-T6A-901 | F80: HD71154-T6A-901 | G80: 45 | H80: 45 | I80: Same | J80: Open
A81: B12 | B81: Random | C81: 1 | D81: FRT LH FENDER SIGNAL LAMP | G81: 65 | H81: 65 | I81: Same | J81: Open
A82: B12 | B82: Random | C82: 2 | D82: LH SIDE MIRROR | G82: 500 | H82: 500 | I82: Same | J82: Open
A83: B12 | B83: Random | C83: 3 | D83: FRT LH DOOR PROTECTOR | G83: 295 | H83: 295 | I83: Same | J83: Open
A84: B12 | B84: Random | C84: 4 | D84: REAR LH DOOR PROTECTOR | G84: 295 | H84: 295 | I84: Same | J84: Open
A85: B12 | B85: Random | C85: 5 | D85: DOOR PROTECTOR CLIPS | G85: 5 | H85: 5 | I85: Same | J85: Open
A86: B12 | B86: Random | C86: 6 | D86: FRT BUMPER | G86: 495 | H86: 495 | I86: Same | J86: Open
A87: B12 | B87: Random | C87: 7 | D87: FRT BUMPER CLIPS | G87: 5 | H87: 5 | I87: Same | J87: Open
A88: B13 | B88: Random | C88: 1 | D88: CLIPS | G88: 70 | H88: 70 | I88: Same | J88: Open
A89: B14 | B89: Random | C89: 1 | D89: RR BOOT TRIM BOARD | E89: T67751-26080 | F89: T67751-26080 | G89: 160 | H89: 160 | I89: Same | J89: Open
A90: B15 | B90: Random | C90: 1 | D90: HOOD | E90: J5900A623 | F90: J5900A623 | G90: 350 | H90: 350 | I90: Same | J90: Open
A91: B15 | B91: Random | C91: 2 | D91: INSULATOR,HOOD (*) | E91: J5915A302 | F91: J5915A302 | G91: 120 | H91: 120 | I91: Same | J91: Open
A92: B15 | B92: Random | C92: 3 | D92: CLIP,HOOD INSULATOR | E92: JMU001282 | F92: JMU001282 | G92: 2 | H92: 2 | I92: Same | J92: Open
A93: B15 | B93: Random | C93: 4 | D93: HINGE,HOOD,LH(*) | E93: J5905A157 | F93: J5905A157 | G93: 50 | H93: 50 | I93: Same | J93: Open
A94: B15 | B94: Random | C94: 5 | D94: HINGE,HOOD,RH(*) | E94: J5905A158 | F94: J5905A158 | G94: 50 | H94: 50 | I94: Same | J94: Open
A95: B15 | B95: Random | C95: 6 | D95: LATCH,HOOD(*) | E95: J5908A186 | F95: J5908A186 | G95: 55 | H95: 55 | I95: Same | J95: Open
A96: B15 | B96: Random | C96: 7 | D96: *GARNISH,FR DECK | E96: J7405A471 | F96: J7405A471 | G96: 150 | H96: 150 | I96: Same | J96: Open
A97: B15 | B97: Random | C97: 8 | D97: COVER,FR DECK,LH | E97: J7405A555 | F97: J7405A555 | G97: 25 | H97: 25 | I97: Same | J97: Open
A98: B15 | B98: Random | C98: 9 | D98: GRILLE,RADIATOR (*) | E98: J6402A377 | F98: J6402A377 | G98: 300 | H98: 300 | I98: Same | J98: Open
A99: B15 | B99: Random | C99: 10 | D99: MARK,THREE-DIA(*) | E99: J7415A603 | F99: J7415A603 | G99: 30 | H99: 30 | I99: Same | J99: Open
A100: B15 | B100: Random | C100: 11 | D100: FACE,FR BUMPER(*) | E100: J6400H293 | F100: J6400H293 | G100: 320 | H100: 320 | I100: Same | J100: Open
... A171: B22 | B171: Random | C171: 7 | D171: Ped Pro Pressure Tube Sensor (PTS) | E171: 1735514-00-A | F171: 1735514-00-A | G171: 46.04 | H171: 46.04 | I171: Same | J171: Open
A172: B23 | B172: Random | C172: 1 | D172: LHS rear last compartment door | G172: 1500 | H172: 1500 | I172: Same | J172: Open
A173: B23 | B173: Random | C173: 2 | D173: LHS rear last second compartment door | G173: 1500 | H173: 1500 | I173: Same | J173: Open
A174: B24 | B174: Random | C174: 1 | D174: BOOT LAMP RH | E174: T81580-33470 | F174: T81580-33470 | G174: 480 | H174: 480 | I174: Same | J174: Open
A175: B24 | B175: Random | C175: 2 | D175: TAILLIGHT UNIT RH | E175: T81551-33590 | F175: T81551-33590 | G175: 585 | H175: 585 | I175: Same | J175: Open
...

Sheet 6. Bills
A1: Bill | B1: Random or hand-picked | C1: Why it was hand-picked | D1: Insurer | E1: Car make | F1: Supplier | G1: Bill number | H1: Bill date | I1: Lines | J1: In the spot check? | K1: Open the bill
A2: B01 | B2: Random | D2: Etiqa Insurance Pte Ltd | E2: KIA | F2: MIN GHEE AUTO PTE LTD | G2: 8415603 | H2: 11/12/2025 | I2: 10 | K2: Open
A3: B02 | B3: Random | D3: AIG Asia Pacific Insurance Pte. Ltd. | E3: NISSAN | F3: JAE AUTO PTE LTD | G3: AR202510-00529 | H3: 01/10/2025 | I3: 1 | K3: Open
A4: B03 | B4: Random | D4: Allianz Insurance Singapore Pte. Ltd. | E4: TESLA | F4: Tesla | G4: 5528313 | I4: 3 | K4: Open
A5: B04 | B5: Random | D5: Allianz Insurance Singapore Pte. Ltd. | E5: SCANIA | F5: Scania Singapore Pte Ltd | G5: 151248 | H5: 30/07/2025 | I5: 13 | J5: Yes | K5: Open
A6: B05 | B6: Random | D6: Tokio Marine Insurance Singapore Ltd | E6: OPEL | F6: JAE AUTO PTE LTD | G6: AR202511-05889 | H6: 13/11/2025 | I6: 18 | K6: Open
A7: B06 | B7: Random | D7: AIG Asia Pacific Insurance Pte. Ltd. | E7: LEXUS | F7: HE XING AUTO PARTS PTE LTD | G7: DLI9285054 | H7: 25/10/2025 | I7: 7 | K7: Open
A8: B07 | B8: Random | D8: Allianz Insurance Singapore Pte. Ltd. | E8: BMW | F8: JAE AUTO PTE LTD | G8: AR202511-08635 | H8: 20/11/2025 | I8: 2 | K8: Open
A9: B08 | B9: Random | D9: Singapore Life Ltd | E9: BYD | F9: HE XING AUTO PARTS PTE LTD | G9: DLI9284776 | H9: 09/10/2025 | I9: 15 | J9: Yes | K9: Open
A10: B09 | B10: Random | D10: ECICS Limited | E10: HYUNDAI | F10: JAE AUTO PTE LTD | G10: AR202512-04887 | H10: 10/12/2025 | I10: 2 | J10: Yes | K10: Open
A11: B10 | B11: Random | D11: Allianz Insurance Singapore Pte. Ltd. | E11: VOLKSWAGEN | F11: JAE AUTO PTE LTD | G11: AR202510-05495 | H11: 13/10/2025 | I11: 1 | K11: Open
A12: B11 | B12: Random | D12: AIG Asia Pacific Insurance Pte. Ltd. | E12: HONDA | F12: MIN GHEE AUTO PTE LTD | G12: 8410969 | H12: 03/11/2025 | I12: 6 | K12: Open
A13: B12 | B13: Random | D13: Tokio Marine Insurance Singapore Ltd | E13: PEUGEOT | F13: TRANS HUA AUTO PTE LTD | G13: A10061453 | H13: 08/09/2025 | I13: 7 | K13: Open
A14: B13 | B14: Random | D14: AIG Asia Pacific Insurance Pte. Ltd. | E14: SUZUKI | F14: Lion's Auto Trading Pte Ltd | G14: A12656 | H14: 04/09/2025 | I14: 1 | K14: Open
A15: B14 | B15: Random | D15: Allianz Insurance Singapore Pte. Ltd. | E15: TOYOTA | F15: JAE AUTO PTE LTD | G15: AR202509-08012 | H15: 18/09/2025 | I15: 1 | J15: Yes | K15: Open
A16: B15 | B16: Random | D16: EQ Insurance Company Ltd | E16: MITSUBISHI | F16: YEW HENG AUTO PARTS PTE LTD | G16: YLI1315864 | H16: 13/06/2025 | I16: 42 | K16: Open
A17: B16 | B17: Random | D17: Singapore Life Ltd | E17: SKODA | F17: HE XING AUTO PARTS PTE LTD | G17: DLI9285818 | H17: 02/12/2025 | I17: 8 | K17: Open
A18: B17 | B18: Random | D18: AIG Asia Pacific Insurance Pte. Ltd. | E18: MAZDA | F18: JAE AUTO PTE LTD | G18: AR202508-09301 | H18: 22/08/2025 | I18: 1 | K18: Open
A19: B18 | B19: Random | D19: Great Eastern General Insurance Limited-MERCEDES | E19: BENZ | F19: MIN GHEE AUTO PTE LTD | G19: 8412421 | H19: 14/11/2025 | I19: 1 | K19: Open
A20: B19 | B20: Random | D20: AIG Asia Pacific Insurance Pte. Ltd. | E20: SUBARU | F20: JAE AUTO PTE LTD | G20: AR202512-11256 | H20: 26/12/2025 | I20: 3 | J20: Yes | K20: Open
A21: B20 | B21: Random | D21: Etiqa Insurance Pte Ltd | E21: KIA | F21: YEW HENG AUTO PARTS PTE LTD | G21: YLI1322004 | H21: 12/12/2025 | I21: 6 | K21: Open
A22: B21 | B22: Random | D22: HL Assurance Pte Ltd | E22: NISSAN | F22: LESUN AUTO PARTS PTE LTD | G22: LL10325981 | H22: 12/08/2025 | I22: 14 | K22: Open
A23: B22 | B23: Random | D23: Allianz Insurance Singapore Pte. Ltd. | E23: TESLA | G23: EPC-5199563-1 | I23: 7 | K23: Open
A24: B23 | B24: Random | D24: Allianz Insurance Singapore Pte. Ltd. | E24: SCANIA | F24: J & C General Supplies Pte Ltd | G24: 071525 | H24: 15/07/2025 | I24: 2 | K24: Open
A25: B24 | B25: Random | D25: EQ Insurance Company Ltd | E25: LEXUS | F25: HE XING AUTO PARTS PTE LTD | G25: DLI9284577 | H25: 29/09/2025 | I25: 17 | K25: Open
A26: B25 | B26: Random | D26: Allianz Insurance Singapore Pte. Ltd. | E26: BMW | F26: JAE AUTO PTE LTD | G26: AR202511-08848 | H26: 21/11/2025 | I26: 2 | K26: Open
A27: B26 | B27: Random | D27: Etiqa Insurance Pte Ltd | E27: BYD | F27: HE XING AUTO PARTS PTE LTD | G27: DLI9286143 | H27: 19/12/2025 | I27: 4 | K27: Open
A28: B27 | B28: Random | D28: Tokio Marine Insurance Singapore Ltd | E28: HYUNDAI | F28: JAE AUTO PTE LTD | G28: AR202510-12366 | H28: 30/10/2025 | I28: 14 | K28: Open
A29: B28 | B29: Random | D29: Allianz Insurance Singapore Pte. Ltd. | E29: VOLKSWAGEN | F29: JAE AUTO PTE LTD | G29: AR202510-04189 | H29: 09/10/2025 | I29: 1 | K29: Open
A30: B29 | B30: Random | D30: AIG Asia Pacific Insurance Pte. Ltd. | E30: HONDA | F30: MIN GHEE AUTO PTE LTD | G30: 8417216 | H30: 26/12/2025 | I30: 6 | K30: Open
A31: B30 | B31: Random | D31: Allianz Insurance Singapore Pte. Ltd. | E31: TOYOTA | F31: JAE AUTO PTE LTD | G31: AR202509-07820 | H31: 17/09/2025 | I31: 1 | K31: Open
A32: B31 | B32: Hand-picked | C32: part number looks misread; price far from similar parts | D32: Allianz Insurance Singapore Pte. Ltd. | E32: TESLA | F32: Tesla Motors Singapore Private Limited | G32: 2040R0000004181 | H32: 2025/07/31 | I32: 15 | K32: Open
A33: B32 | B33: Hand-picked | C33: part number looks misread; price far from similar parts | D33: Allianz Insurance Singapore Pte. Ltd. | E33: TESLA | F33: Tesla | I33: 15 | K33: Open
A34: B33 | B34: Hand-picked | C34: price far from similar parts; same part number used for different items | D34: HL Assurance Pte Ltd | E34: TOYOTA | F34: HE XING AUTO PARTS PTE LTD | G34: DLI9285374 | H34: 10/11/2025 | I34: 14 | K34: Open
A35: B34 | B35: Hand-picked | C35: part number looks misread | D35: AIG Asia Pacific Insurance Pte. Ltd. | E35: TOYOTA | F35: JAE AUTO PTE LTD | G35: AR202601-08997 | H35: 21/01/2026 | I35: 21 | K35: Open
A36: B35 | B36: Hand-picked | C36: price far from similar parts | D36: Allianz Insurance Singapore Pte. Ltd.-MERCEDES | E36: BENZ | F36: MIN GHEE AUTO PTE LTD | G36: 8397352 | H36: 03/07/2025 | I36: 13 | K36: Open
A37: B36 | B37: Hand-picked | C37: price far from similar parts | D37: ECICS Limited | E37: TOYOTA | F37: JAE AUTO PTE LTD | G37: AR202601-05752 | H37: 14/01/2026 | I37: 16 | K37: Open
A38: B37 | B38: Hand-picked | C38: part number looks misread | D38: Tokio Marine Insurance Singapore Ltd-MERCEDES | E38: BENZ | F38: SURPASS AUTO PARTS SUPPLIES PTE LTD | G38: 25080083 | H38: 01/08/2025 | I38: 26 | K38: Open
A39: B38 | B39: Hand-picked | C39: price far from similar parts | D39: Allianz Insurance Singapore Pte. Ltd. | E39: TESLA | F39: Tesla Motors Singapore Private Limited | G39: 2040R0000004919 | H39: 20/11/2025 | I39: 10 | K39: Open
A40: B39 | B40: Hand-picked | C40: letter mixed into a number | D40: EQ Insurance Company Ltd | E40: TOYOTA | F40: JAE AUTO PTE LTD | G40: AR202509-09589 | H40: 22/09/2025 | I40: 9 | K40: Open
...
