Workbook

Sheet 1. Start here
B1: Are the big price ranges real?
B2: A check on why some parts show a very wide price range in the price reference
B4: What this is about
B5: The price reference groups together lines from supplier bills that describe the same part, and reports the typical price for each group (the middle price, so one unusual bill does not move it much). Some groups have a very wide range. For example the Toyota headlamp group runs from S$185 to S$3600.
B6: There are two possible explanations, and they lead to different fixes:
B7: • The prices really do vary for the same part. The typical price is still fine to use.
B8: • The group has lumped different parts together because their names look alike (a small clip with a whole bumper, or a headlamp for one car with a headlamp for another). Then the typical price is misleading, and the way parts are grouped needs fixing.
B10: What we checked
B11: 16 groups, 106 bill lines in total:
B12: • 11 groups with the widest price ranges (78 lines).
B13: • 5 comparison groups whose prices are fairly close (28 lines). These should come back as "same part". If they don't, the checking is being too strict.
B14: Of the 106 lines, 97 have the scanned bill on this computer (click Open). The other 9 are older 2018 bills added from a spreadsheet, so only our typed-up record is available.
B16: What we already know
B17: When the part number is exactly the same | C17: Prices agree | D17: Across the whole reference, the same part number from different suppliers costs almost exactly the same (typical difference: none). So where we know it is the same part, prices are not wildly different.
B18: The headlamp group | C18: 14 prices, 13 different part numbers | D18: Almost every bill in it is for a different part number. That suggests different headlamps grouped together, not one headlamp at many prices. This file lets a person confirm it.
B19: Comparing similar parts by car model | C19: Did not help | D19: Keeping only lines for the same car model halved the number of usable groups without narrowing the ranges.
B21: What we need from you (about 2 hours)
B22: Step 1. Sheet "2. Check each line" (106 lines). For each line, click Open to see the bill and Search to look up the part number online. Write what the part is and which car it fits, then pick a reason from the drop-down in the yellow column. Lines are listed cheapest first within each group.
B23: Step 2. Sheet "3. Price groups" (16 groups). Once a group's lines are done, pick a verdict for the whole group.
B24: Step 3. Sheet "4. Results" fills itself in and gives the answer.
B25: Tip: judge each line against what most of the group is (e.g. a full headlamp), not against the price. Looking up prices online is optional: Singapore prices are hard to find online and overseas prices are not comparable.
B27: What the reasons mean
B28: Same part, price just varies | C28: It really is the same part. The price difference is genuine (different supplier, date or deal).
B29: Smaller piece of the part | C29: A clip, bracket, cover or other small piece, grouped with the full part (e.g. a S$5 bumper clip next to a S$600 bumper).
B30: Same name, different car | C30: Same kind of part, but made for a different car model, so not interchangeable.
B31: Different position (front/rear etc.) | C31: Front vs rear, upper vs lower, or inner vs outer.
B32: Different quality (genuine/copy/used) | C32: Genuine maker's part vs a copy (aftermarket) or a used/reconditioned one.
B33: Priced as a pair or set | C33: The line charges for two (left and right) or a kit, not one piece.
B34: Reading mistake on our record | C34: Our record has the wrong part number or price compared with the bill itself.
B35: Can't tell | C35: Not enough information on the bill or online to decide.
B37: Words used in this file
B38: Group | C38: Bill lines the price reference treats as the same part. Each group gets one typical price.
B39: Typical price | C39: The middle price in the group: half the prices are below it, half above.
B40: Part number | C40: The maker's code printed on the bill that identifies the exact part (for example 81130-0L011).
B41: × typical | C41: How a line's price compares with its group's typical price. 2.0 means twice the typical price, 0.5 means half.
B43: Files: made from PartsIndex_data_validation_2026-10-15.xlsx. Scanned bills are in /home/jason/mm-parts-index/invoices. Price reference snapshot PIX-335e1802-6b06668c, taken 2026-10-15.

Sheet 2. Check each line
A1: Group | B1: Group name | C1: Comparison group? | D1: Price on this bill (S$) | E1: × typical | F1: Description on the bill | G1: Part number on the bill | H1: Car make | I1: Car model | J1: Supplier | K1: Bill number | L1: Bill date | M1: Bill file name | N1: Open the bill | O1: Look it up | P1: WHAT IS THIS PART? | Q1: WHICH CAR DOES IT FIT? | R1: REASON (pick from list) | S1: Price found online (S$, optional) | T1: Where you found it (link) | U1: Your notes
A2: C01 | B2: Cover Bumper | D2: 5 | E2: 0.04 | F2: COVER BUMPER | G2: MBA000 991 36 04 | H2: Mercedes-Benz | I2: — | J2: MIN GHEE AUTO PTE LTD | K2: 8414503 | L2: 03/12/2025 | M2: 2026-01-05-Allianz Insurance Singapore Pte. Ltd.-MERCEDES-BENZ-132.PDF | N2: Open | O2: Search
A3: C01 | B3: Cover Bumper | D3: 32 | E3: 0.27 | F3: Cover Bumper | G3: MBA213 885 16 00 | H3: Mercedes-Benz | I3: — | J3: Min Ghee Auto Pte Ltd | K3: 8122844 | L3: 10/04/2018 | M3: No scanned copy on this computer (older bill, added from a spreadsheet) | N3: – | O3: Search
A4: C01 | B4: Cover Bumper | D4: 80 | E4: 0.67 | F4: COVER, BUMPER AREA | G4: MBA156 880 41 00 | H4: Mercedes-Benz | I4: — | J4: MIN GHEE AUTO PTE LTD | K4: 8397352 | L4: 03/07/2025 | M4: 2025-08-17-Allianz Insurance Singapore Pte. Ltd.-MERCEDES-BENZ-6.JPG | N4: Open | O4: Search
A5: C01 | B5: Cover Bumper | D5: 120 | E5: 1 | F5: COVER BUMPER AREA | G5: MBA205 885 31 23 | H5: Mercedes-Benz | I5: — | J5: MIN GHEE AUTO PTE. LTD. | K5: 8407516 | L5: 01/10/2025 | M5: 2025-10-15-AIG Asia Pacific Insurance Pte. Ltd.-MERCEDES-BENZ-49.PDF | N5: Open | O5: Search
A6: C01 | B6: Cover Bumper | D6: 120 | E6: 1 | F6: COVER BUMPER | G6: MBA003 990 94 97/CUPPED BLIND RI | H6: Mercedes-Benz | I6: — | J6: MIN GHEE AUTO PTE LTD | K6: 8414503 | L6: 03/12/2025 | M6: 2026-01-05-Allianz Insurance Singapore Pte. Ltd.-MERCEDES-BENZ-132.PDF | N6: Open | O6: Search
A7: C01 | B7: Cover Bumper | D7: 270 | E7: 2.25 | F7: COVER BUMPER AREA | G7: MBA253 885 05 22 | H7: Mercedes-Benz | I7: — | J7: MIN GHEE AUTO PTE LTD | K7: 8405253 | L7: 11/09/2025 | M7: 2025-10-17-AIG Asia Pacific Insurance Pte. Ltd.-MERCEDES-BENZ-55.PDF | N7: Open | O7: Search
A8: C01 | B8: Cover Bumper | D8: 620 | E8: 5.17 | F8: COVER, BUMPER AREA | G8: MBA156 880 46 00 | H8: Mercedes-Benz | I8: — | J8: MIN GHEE AUTO PTE LTD | K8: 8397352 | L8: 03/07/2025 | M8: 2025-08-17-Allianz Insurance Singapore Pte. Ltd.-MERCEDES-BENZ-6.JPG | N8: Open | O8: Search
A9: C02 | B9: HEADLAMP LH | D9: 185 | E9: 0.39 | F9: HEADLAMP RH | G9: T81130-37203R | H9: Toyota | I9: — | J9: Precision Auto Parts Supplies Pte Ltd | K9: INV-0463 | L9: 29/09/2025 | M9: 2025-10-08-AIG Asia Pacific Insurance Pte. Ltd.-TOYOTA-45.PDF | N9: Open | O9: Search
A10: C02 | B10: HEADLAMP LH | D10: 185 | E10: 0.39 | F10: HEADLAMP LH | G10: T81170-37203R | H10: Toyota | I10: — | J10: Precision Auto Parts Supplies Pte Ltd | K10: INV-0463 | L10: 29/09/2025 | M10: 2025-10-08-AIG Asia Pacific Insurance Pte. Ltd.-TOYOTA-45.PDF | N10: Open | O10: Search
A11: C02 | B11: HEADLAMP LH | D11: 250 | E11: 0.53 | F11: HEADLAMP RH | G11: ZZT81130-0L010 | H11: Toyota | I11: KDH201 | J11: FORTUNA AUTOMOTIVE PTE LTD | K11: CL2508266 | L11: 14/08/2025 | M11: 2025-11-24-Tokio Marine Insurance Singapore Ltd-TOYOTA-81.PDF | N11: Open | O11: Search
A12: C02 | B12: HEADLAMP LH | D12: 270 | E12: 0.57 | F12: HEADLAMP LH | G12: ZZT81170-02F31 | H12: Toyota | I12: ZRE171 | J12: FORTUNA AUTOMOTIVE PTE LTD | K12: CL2508534 | L12: 27/08/2025 | M12: 2025-09-17-AIG Asia Pacific Insurance Pte. Ltd.-TOYOTA-21.PDF | N12: Open | O12: Search
A13: C02 | B13: HEADLAMP LH | D13: 270 | E13: 0.57 | F13: HEADLAMP | G13: T81130-37660 | H13: Toyota | I13: ZRE171 | J13: FORTUNA AUTOMOTIVE PTE LTD | K13: CL2508534 | L13: 27/08/2025 | M13: 2025-09-17-AIG Asia Pacific Insurance Pte. Ltd.-TOYOTA-21.PDF | N13: Open | O13: Search
... A24: C03 | B24: ASSEMBLY - FENDER SUPPORT - LEFT HAND | D24: 24.82 | E24: 0.06 | F24: ASSEMBLY - FENDER SUPPORT - LEFT HAND | G24: 1771936-SC-C | H24: Tesla | I24: Model 3 | J24: Tesla Motors Singapore Private Limited | K24: 2040R0000004919 | L24: 20/11/2025 | M24: 2026-02-09-Allianz Insurance Singapore Pte. Ltd.-TESLA-169.PDF | N24: Open | O24: Search
A25: C03 | B25: ASSEMBLY - FENDER SUPPORT - LEFT HAND | D25: 24.82 | E25: 0.06 | F25: ASSEMBLY - FENDER SUPPORT - LEFT HAND | G25: 1771936-SC-C | H25: Tesla | I25: Model 3 | J25: Tesla | M25: 2026-02-09-Allianz Insurance Singapore Pte. Ltd.-TESLA-173.JPG | N25: Open | O25: Search
A26: C03 | B26: ASSEMBLY - FENDER SUPPORT - LEFT HAND | D26: 436.29 | E26: 1 | F26: ASSEMBLY - FENDER - LEFT HAND | G26: 1714884-EC-D | H26: Tesla | I26: — | J26: Tesla Motors Singapore Private Limited | K26: 2040R0000004181 | L26: 2025/07/31 | M26: 2026-02-09-Allianz Insurance Singapore Pte. Ltd.-TESLA-155.PDF | N26: Open | O26: Search
A27: C03 | B27: ASSEMBLY - FENDER SUPPORT - LEFT HAND | D27: 436.29 | E27: 1 | F27: ASSEMBLY - FENDER - LEFT HAND | G27: 1714884-EC-D | H27: Tesla | I27: Model 3 | J27: Tesla Motors Singapore Private Limited | K27: 2040R0000004919 | L27: 20/11/2025 | M27: 2026-02-09-Allianz Insurance Singapore Pte. Ltd.-TESLA-169.PDF | N27: Open | O27: Search
A28: C03 | B28: ASSEMBLY - FENDER SUPPORT - LEFT HAND | D28: 436.29 | E28: 1 | F28: ASSEMBLY - FENDER - LEFT HAND | G28: 1714884-EC-D | H28: Tesla | I28: Model 3 | J28: Tesla | M28: 2026-02-09-Allianz Insurance Singapore Pte. Ltd.-TESLA-173.JPG | N28: Open | O28: Search
A29: C03 | B29: ASSEMBLY - FENDER SUPPORT - LEFT HAND | D29: 436.29 | E29: 1 | F29: ASSEMBLY - FENDER - LEFT HAND | G29: 1714884-EC-D | H29: Tesla | I29: — | J29: Tesla | L29: 28/11/2025 | M29: 2026-02-09-Allianz Insurance Singapore Pte. Ltd.-TESLA-173.JPG | N29: Open | O29: Search
A30: C04 | B30: Mounting Rail | D30: 10 | E30: 0.24 | F30: Mounting Rail | G30: MBA213 885 06 21 | H30: Mercedes-Benz | I30: — | J30: Min Ghee Auto Pte Ltd | K30: 8123192 | L30: 10/08/2018 | M30: No scanned copy on this computer (older bill, added from a spreadsheet) | N30: – | O30: Search
A31: C04 | B31: Mounting Rail | D31: 20 | E31: 0.47 | F31: MOUNTING RAIL | G31: MBA253 885 67 01 | H31: Mercedes-Benz | I31: — | J31: MIN GHEE AUTO PTE LTD | K31: 8405253 | L31: 11/09/2025 | M31: 2025-10-17-AIG Asia Pacific Insurance Pte. Ltd.-MERCEDES-BENZ-55.PDF | N31: Open | O31: Search
A32: C04 | B32: Mounting Rail | D32: 65 | E32: 1.53 | F32: MOUNTING RAIL FRT LH | G32: A4478800612 | H32: Mercedes-Benz | I32: — | J32: SURPASS AUTO PARTS SUPPLIES PTE LTD | K32: 25080083 | L32: 01/08/2025 | M32: 2026-01-07-Tokio Marine Insurance Singapore Ltd-MERCEDES-BENZ-135.PDF | N32: Open | O32: Search
A33: C04 | B33: Mounting Rail | D33: 65 | E33: 1.53 | F33: MOUNTING RAIL FRT RH | G33: A4478800712 | H33: Mercedes-Benz | I33: — | J33: SURPASS AUTO PARTS SUPPLIES PTE LTD | K33: 25080083 | L33: 01/08/2025 | M33: 2026-01-07-Tokio Marine Insurance Singapore Ltd-MERCEDES-BENZ-135.PDF | N33: Open | O33: Search
A34: C05 | B34: Front Bumper Fog Lamp RH | D34: 20 | E34: 0.21 | F34: Front Bumper Fog Lamp Connector LH | G34: 3D0941165A | H34: Audi | I34: Q5 | J34: Jae Auto Pte Ltd | K34: AR201805-00837 | L34: 05/02/2018 | M34: No scanned copy on this computer (older bill, added from a spreadsheet) | N34: – | O34: Search
A35: C05 | B35: Front Bumper Fog Lamp RH | D35: 95 | E35: 1 | F35: Front Bumper Fog Lamp RH | G35: 8T0941700B | H35: Audi | I35: Q5 | J35: Jae Auto Pte Ltd | K35: AR201805-02365 | L35: 05/05/2018 | M35: No scanned copy on this computer (older bill, added from a spreadsheet) | N35: – | O35: Search
A36: C05 | B36: Front Bumper Fog Lamp RH | D36: 95 | E36: 1 | F36: Front Bumper Fog Lamp LH | G36: 8T0941699B | H36: Audi | I36: Q5 | J36: Jae Auto Pte Ltd | K36: AR201805-03001 | L36: 05/07/2018 | M36: No scanned copy on this computer (older bill, added from a spreadsheet) | N36: – | O36: Search
A37: C05 | B37: Front Bumper Fog Lamp RH | D37: 125 | E37: 1.32 | F37: Front Bumper Fog Lamp Cover LH | G37: 8R0807681M BJI | H37: Audi | I37: Q5 | J37: Jae Auto Pte Ltd | K37: AR201804-1417 | L37: 25/04/2018 | M37: No scanned copy on this computer (older bill, added from a spreadsheet) | N37: – | O37: Search
A38: C05 | B38: Front Bumper Fog Lamp RH | D38: 125 | E38: 1.32 | F38: Front Bumper Fog Lamp Cover RH | G38: 8R0807682J BJI | H38: Audi | I38: Q5 | J38: Jae Auto Pte Ltd | K38: AR201804-1417 | L38: 25/04/2018 | M38: No scanned copy on this computer (older bill, added from a spreadsheet) | N38: – | O38: Search
A39: C06 | B39: FR FENDER LH | D39: 75 | E39: 0.36 | F39: FR FENDER RH | G39: ZZT53801-26011 | H39: Toyota | I39: KDH201 | J39: FORTUNA AUTOMOTIVE PTE LTD | K39: CL2508266 | L39: 14/08/2025 | M39: 2025-11-24-Tokio Marine Insurance Singapore Ltd-TOYOTA-81.PDF | N39: Open | O39: Search
A40: C06 | B40: FR FENDER LH | D40: 85 | E40: 0.4 | F40: FRT FENDER LH | G40: 53802-26031 | H40: Toyota | I40: — | J40: JAE AUTO PTE LTD | K40: AR202511-06143 | L40: 14/11/2025 | M40: 2025-11-29-Allianz Insurance Singapore Pte. Ltd.-TOYOTA-84.PDF | N40: Open | O40: Search
A41: C06 | B41: FR FENDER LH | D41: 90 | E41: 0.43 | F41: FRT FENDER LH | G41: T53802-26021 | H41: Toyota | I41: Hiace KDH200 | J41: JAE AUTO PTE LTD | K41: AR202601-08997 | L41: 21/01/2026 | M41: 2026-02-03-AIG Asia Pacific Insurance Pte. Ltd.-TOYOTA-152.PDF | N41: Open | O41: Search
... A79: C11 | B79: F/B LOWER GRILLE | D79: 220 | E79: 2.93 | F79: F/B LOWER GRILLE | G79: ZZT53102-06120 | H79: Toyota | I79: ASV51 | J79: FORTUNA AUTOMOTIVE PTE LTD | K79: CL2510229 | L79: 15/10/2025 | M79: 2025-10-27-AIG Asia Pacific Insurance Pte. Ltd.-TOYOTA-60.PDF | N79: Open | O79: Search
A80: C12 | B80: BRACKET- FASCIA FRT CTR TO FDR LH | C80: Yes | D80: 7.1 | E80: 0.63 | F80: BRACKET - FASCIA SIDE TO FDR LH | G80: 1774268-00-G | H80: Tesla | I80: — | J80: Tesla Motors Singapore Private Limited | K80: 2040R0000004181 | L80: 2025/07/31 | M80: 2026-02-09-Allianz Insurance Singapore Pte. Ltd.-TESLA-155.PDF | N80: Open | O80: Search
A81: C12 | B81: BRACKET- FASCIA FRT CTR TO FDR LH | C81: Yes | D81: 7.1 | E81: 0.63 | F81: BRACKET - FASCIA SIDE TO FDR LH | G81: 1774268-00-G | H81: Tesla | I81: — | J81: Tesla | K81: EPC-5140005-1 | M81: 2026-02-09-Allianz Insurance Singapore Pte. Ltd.-TESLA-158.JPG | N81: Open | O81: Search
A82: C12 | B82: BRACKET- FASCIA FRT CTR TO FDR LH | C82: Yes | D82: 7.1 | E82: 0.63 | F82: BRACKET - FASCIA SIDE TO FDR LH | G82: 1774268-00-G | H82: Tesla | I82: — | J82: Tesla | L82: 28/11/2025 | M82: 2026-02-09-Allianz Insurance Singapore Pte. Ltd.-TESLA-173.JPG | N82: Open | O82: Search
A83: C12 | B83: BRACKET- FASCIA FRT CTR TO FDR LH | C83: Yes | D83: 11.28 | E83: 1 | F83: BRACKET- FASCIA FRT CTR TO FDR LH | G83: 1734299-00-H | H83: Tesla | I83: Model 3 | J83: Tesla Motors Singapore Private Limited | K83: 2040R0000004325 | L83: 19/08/2025 | M83: 2025-12-02-Allianz Insurance Singapore Pte. Ltd.-TESLA-94.PDF | N83: Open | O83: Search
A84: C12 | B84: BRACKET- FASCIA FRT CTR TO FDR LH | C84: Yes | D84: 11.28 | E84: 1 | F84: BRACKET- FASCIA FRT CTR TO FDR RH | G84: 1734300-00-H | H84: Tesla | I84: — | J84: Tesla Motors Singapore Private Limited | K84: 2040R0000004342 | L84: 22/08/2025 | M84: 2025-12-02-Allianz Insurance Singapore Pte. Ltd.-TESLA-95.PDF | N84: Open | O84: Search
A85: C12 | B85: BRACKET- FASCIA FRT CTR TO FDR LH | C85: Yes | D85: 11.28 | E85: 1 | F85: BRACKET- FASCIA FRT CTR TO FDR LH | G85: 1734299-00-H | H85: Tesla | I85: — | J85: Tesla Motors Singapore Private Limited | K85: 2040R0000004188 | L85: 31/07/2025 | M85: 2026-02-09-Allianz Insurance Singapore Pte. Ltd.-TESLA-156.PDF | N85: Open | O85: Search
A86: C12 | B86: BRACKET- FASCIA FRT CTR TO FDR LH | C86: Yes | D86: 11.28 | E86: 1 | F86: BRACKET-FASCIA FRT CTR TO FDR LH | G86: 1734299-00-H | H86: Tesla | I86: — | J86: Tesla | K86: EPC-5140005-1 | M86: 2026-02-09-Allianz Insurance Singapore Pte. Ltd.-TESLA-158.JPG | N86: Open | O86: Search
A87: C12 | B87: BRACKET- FASCIA FRT CTR TO FDR LH | C87: Yes | D87: 11.28 | E87: 1 | F87: BRACKET- FASCIA FRT CTR TO FDR LH | G87: 1734299-00-H | H87: Tesla | I87: — | J87: Tesla | L87: 28/11/2025 | M87: 2026-02-09-Allianz Insurance Singapore Pte. Ltd.-TESLA-173.JPG | N87: Open | O87: Search
...

Sheet 3. Price groups
A1: Group | B1: Group name | C1: Car make | D1: Why we picked it | E1: Number of prices | F1: Cheapest (S$) | G1: Typical price (S$) | H1: Dearest (S$) | I1: Dearest is … times the cheapest | J1: Different part numbers in the group | K1: Different suppliers | L1: Names used on the bills | M1: Bill files in this group | N1: Lines done | O1: Lines marked "Same part, price just varies" | P1: YOUR VERDICT (pick from list) | Q1: Your notes
A2: C01 | B2: Cover Bumper | C2: Mercedes-Benz | D2: The dearest price is 5 times the cheapest or more; Prices are scattered widely around the typical price | E2: 7 | F2: 5 | G2: 120 | H2: 620 | I2: 124 | J2: 7 | K2: 3 | L2: Cover Bumper COVER, BUMPER AREA COVER BUMPER AREA COVER BUMPER | M2: 2026-01-05-Allianz Insurance Singapore Pte. Ltd.-MERCEDES-BENZ-132.PDF Min Ghee Auto Pte Ltd 8122844 (no scan) 2025-08-17-Allianz Insurance Singapore Pte. Ltd.-MERCEDES-BENZ-6.JPG 2025-10-15-AIG Asia Pacific Insurance Pte. Ltd.-MERCEDES-BENZ-49.PDF 2025-10-17-AIG Asia Pacific Insurance Pte. Ltd.-MERCEDES-BENZ-55.PDF | N2: =COUNTIFS('2. Check each line'!$A$2:$A$107,A2,'2. Check each line'!$R$2:$R$107,"<>")&" of "&COUNTIF('2. Check each line'!$A$2:$A$107,A2) | O2: =COUNTIFS('2. Check each line'!$A$2:$A$107,A2,'2. Check each line'!$R$2:$R$107,"Same part, price just varies")
A3: C02 | B3: HEADLAMP LH | C3: Toyota | D3: The dearest price is 5 times the cheapest or more; Prices are scattered widely around the typical price; Headlamp: the example raised in the meeting | E3: 14 | F3: 185 | G3: 475 | H3: 3600 | I3: 19.5 | J3: 13 | K3: 4 | L3: HEADLAMP LH HEADLAMP HEADLAMP RH HEADLAMP UNIT LH HEADLAMP ASSY LH HEADLAMP UNIT RH | M3: 2025-10-08-AIG Asia Pacific Insurance Pte. Ltd.-TOYOTA-45.PDF 2025-11-24-Tokio Marine Insurance Singapore Ltd-TOYOTA-81.PDF 2025-09-17-AIG Asia Pacific Insurance Pte. Ltd.-TOYOTA-21.PDF 2025-10-27-AIG Asia Pacific Insurance Pte. Ltd.-TOYOTA-60.PDF 2026-02-23-Allianz Insurance Singapore Pte. Ltd.-TOYOTA-179.PDF 2026-01-15-Allianz Insurance Singapore Pte. Ltd.-TOYOTA-140.PDF 2026-01-14-HL Assurance Pte Ltd-TOYOTA-139.PDF 2025-10-21-HL Assurance Pte Ltd-TOYOTA-58.PDF 2026-01-21-HL Assurance Pte Ltd-TOYOTA-146.PDF 2025-11-22-AIG Asia Pacific Insurance Pte. Ltd.-LEXUS-80.PDF 2025-12-03-Allianz Insurance Singapore Pte. Ltd.-TOYOTA-101.PDF | N3: =COUNTIFS('2. Check each line'!$A$2:$A$107,A3,'2. Check each line'!$R$2:$R$107,"<>")&" of "&COUNTIF('2. Check each line'!$A$2:$A$107,A3) | O3: =COUNTIFS('2. Check each line'!$A$2:$A$107,A3,'2. Check each line'!$R$2:$R$107,"Same part, price just varies")
A4: C03 | B4: ASSEMBLY - FENDER SUPPORT - LEFT HAND | C4: Tesla | D4: The dearest price is 5 times the cheapest or more; Prices are scattered widely around the typical price | E4: 7 | F4: 24.82 | G4: 436.29 | H4: 436.29 | I4: 17.6 | J4: 3 | K4: 2 | L4: ASSEMBLY - FENDER SUPPORT - LEFT HAND ASSEMBLY - FENDER - LEFT HAND | M4: 2026-02-09-Allianz Insurance Singapore Pte. Ltd.-TESLA-155.PDF 2026-02-09-Allianz Insurance Singapore Pte. Ltd.-TESLA-169.PDF 2026-02-09-Allianz Insurance Singapore Pte. Ltd.-TESLA-173.JPG | N4: =COUNTIFS('2. Check each line'!$A$2:$A$107,A4,'2. Check each line'!$R$2:$R$107,"<>")&" of "&COUNTIF('2. Check each line'!$A$2:$A$107,A4) | O4: =COUNTIFS('2. Check each line'!$A$2:$A$107,A4,'2. Check each line'!$R$2:$R$107,"Same part, price just varies")
A5: C04 | B5: Mounting Rail | C5: Mercedes-Benz | D5: The dearest price is 5 times the cheapest or more; Prices are scattered widely around the typical price | E5: 4 | F5: 10 | G5: 42.5 | H5: 65 | I5: 6.5 | J5: 4 | K5: 3 | L5: Mounting Rail MOUNTING RAIL MOUNTING RAIL FRT LH MOUNTING RAIL FRT RH | M5: Min Ghee Auto Pte Ltd 8123192 (no scan) 2025-10-17-AIG Asia Pacific Insurance Pte. Ltd.-MERCEDES-BENZ-55.PDF 2026-01-07-Tokio Marine Insurance Singapore Ltd-MERCEDES-BENZ-135.PDF | N5: =COUNTIFS('2. Check each line'!$A$2:$A$107,A5,'2. Check each line'!$R$2:$R$107,"<>")&" of "&COUNTIF('2. Check each line'!$A$2:$A$107,A5) | O5: =COUNTIFS('2. Check each line'!$A$2:$A$107,A5,'2. Check each line'!$R$2:$R$107,"Same part, price just varies")
A6: C05 | B6: Front Bumper Fog Lamp RH | C6: Audi | D6: The dearest price is 5 times the cheapest or more | E6: 5 | F6: 20 | G6: 95 | H6: 125 | I6: 6.3 | J6: 5 | K6: 1 | L6: Front Bumper Fog Lamp RH Front Bumper Fog Lamp LH Front Bumper Fog Lamp Connector LH Front Bumper Fog Lamp Cover LH Front Bumper Fog Lamp Cover RH | M6: Jae Auto Pte Ltd AR201805-00837 (no scan) Jae Auto Pte Ltd AR201805-02365 (no scan) Jae Auto Pte Ltd AR201805-03001 (no scan) Jae Auto Pte Ltd AR201804-1417 (no scan) | N6: =COUNTIFS('2. Check each line'!$A$2:$A$107,A6,'2. Check each line'!$R$2:$R$107,"<>")&" of "&COUNTIF('2. Check each line'!$A$2:$A$107,A6) | O6: =COUNTIFS('2. Check each line'!$A$2:$A$107,A6,'2. Check each line'!$R$2:$R$107,"Same part, price just varies")
A7: C06 | B7: FR FENDER LH | C7: Toyota | D7: The dearest price is 5 times the cheapest or more; Prices are scattered widely around the typical price | E7: 9 | F7: 75 | G7: 210 | H7: 380 | I7: 5.1 | J7: 8 | K7: 3 | L7: FR FENDER LH FR FENDER RH FRT FENDER LH FRT FENDER RH | M7: 2025-11-24-Tokio Marine Insurance Singapore Ltd-TOYOTA-81.PDF 2025-11-29-Allianz Insurance Singapore Pte. Ltd.-TOYOTA-84.PDF 2026-02-03-AIG Asia Pacific Insurance Pte. Ltd.-TOYOTA-152.PDF 2025-12-05-Tokio Marine Insurance Singapore Ltd-TOYOTA-106.PDF 2025-10-21-HL Assurance Pte Ltd-TOYOTA-58.PDF 2026-01-14-HL Assurance Pte Ltd-TOYOTA-139.PDF 2026-02-25-ECICS Limited-TOYOTA-181.PDF 2025-11-22-AIG Asia Pacific Insurance Pte. Ltd.-LEXUS-80.PDF 2026-01-21-HL Assurance Pte Ltd-TOYOTA-146.PDF | N7: =COUNTIFS('2. Check each line'!$A$2:$A$107,A7,'2. Check each line'!$R$2:$R$107,"<>")&" of "&COUNTIF('2. Check each line'!$A$2:$A$107,A7) | O7: =COUNTIFS('2. Check each line'!$A$2:$A$107,A7,'2. Check each line'!$R$2:$R$107,"Same part, price just varies")
A8: C07 | B8: FRT BUMPER GRILLE LH | C8: Toyota | D8: The dearest price is 5 times the cheapest or more; Prices are scattered widely around the typical price | E8: 8 | F8: 40 | G8: 82.5 | H8: 200 | I8: 5 | J8: 4 | K8: 1 | L8: FRT BUMPER GRILLE LH FRT BUMPER LWR GRILLE | M8: 2025-11-29-Allianz Insurance Singapore Pte. Ltd.-TOYOTA-91.PDF 2025-09-26-EQ Insurance Company Ltd-TOYOTA-26.PDF 2025-09-26-EQ Insurance Company Ltd-TOYOTA-29.PDF 2025-11-29-Allianz Insurance Singapore Pte. Ltd.-TOYOTA-90.PDF 2025-12-05-Tokio Marine Insurance Singapore Ltd-TOYOTA-106.PDF 2026-02-03-AIG Asia Pacific Insurance Pte. Ltd.-TOYOTA-152.PDF 2026-02-25-ECICS Limited-TOYOTA-181.PDF 2025-11-19-Tokio Marine Insurance Singapore Ltd-TOYOTA-74.PDF | N8: =COUNTIFS('2. Check each line'!$A$2:$A$107,A8,'2. Check each line'!$R$2:$R$107,"<>")&" of "&COUNTIF('2. Check each line'!$A$2:$A$107,A8) | O8: =COUNTIFS('2. Check each line'!$A$2:$A$107,A8,'2. Check each line'!$R$2:$R$107,"Same part, price just varies")
A9: C08 | B9: SUPPORT PANEL | C9: Toyota | D9: Prices are scattered widely around the typical price | E9: 6 | F9: 135 | G9: 185 | H9: 600 | I9: 4.4 | J9: 4 | K9: 2 | L9: SUPPORT PANEL SUPPORT PANEL 11" SUPPORT PANEL TOP | M9: 2026-02-02-AIG Asia Pacific Insurance Pte. Ltd.-TOYOTA-151.PDF 2025-11-29-Allianz Insurance Singapore Pte. Ltd.-TOYOTA-83.PDF 2025-11-18-AIG Asia Pacific Insurance Pte. Ltd.-TOYOTA-72.PDF 2026-02-03-AIG Asia Pacific Insurance Pte. Ltd.-TOYOTA-152.PDF 2025-12-05-Tokio Marine Insurance Singapore Ltd-TOYOTA-106.PDF 2026-01-21-HL Assurance Pte Ltd-TOYOTA-146.PDF | N9: =COUNTIFS('2. Check each line'!$A$2:$A$107,A9,'2. Check each line'!$R$2:$R$107,"<>")&" of "&COUNTIF('2. Check each line'!$A$2:$A$107,A9) | O9: =COUNTIFS('2. Check each line'!$A$2:$A$107,A9,'2. Check each line'!$R$2:$R$107,"Same part, price just varies")
A10: C09 | B10: CARRIER | C10: Mercedes-Benz | D10: Prices are scattered widely around the typical price | E10: 5 | F10: 195 | G10: 280 | H10: 820 | I10: 4.2 | J10: 5 | K10: 1 | L10: CARRIER ASSY. CARRIER, FRONT | M10: 2025-08-17-Allianz Insurance Singapore Pte. Ltd.-MERCEDES-BENZ-6.JPG 2026-01-05-Allianz Insurance Singapore Pte. Ltd.-MERCEDES-BENZ-132.PDF | N10: =COUNTIFS('2. Check each line'!$A$2:$A$107,A10,'2. Check each line'!$R$2:$R$107,"<>")&" of "&COUNTIF('2. Check each line'!$A$2:$A$107,A10) | O10: =COUNTIFS('2. Check each line'!$A$2:$A$107,A10,'2. Check each line'!$R$2:$R$107,"Same part, price just varies")
A11: C10 | B11: Head Lamp RH 09" (TH) | C11: Toyota | D11: Prices are scattered widely around the typical price; Headlamp: the example raised in the meeting | E11: 9 | F11: 310 | G11: 350 | H11: 1100 | I11: 3.5 | J11: 9 | K11: 2 | L11: Head Lamp RH 09" (TH) HEAD LAMP RH HEAD LAMP LH | M11: Jae Auto Pte Ltd AR201806-15561 (no scan) 2025-11-29-Allianz Insurance Singapore Pte. Ltd.-TOYOTA-83.PDF 2025-11-19-Tokio Marine Insurance Singapore Ltd-TOYOTA-74.PDF 2025-12-05-Tokio Marine Insurance Singapore Ltd-TOYOTA-106.PDF 2026-02-25-ECICS Limited-TOYOTA-181.PDF | N11: =COUNTIFS('2. Check each line'!$A$2:$A$107,A11,'2. Check each line'!$R$2:$R$107,"<>")&" of "&COUNTIF('2. Check each line'!$A$2:$A$107,A11) | O11: =COUNTIFS('2. Check each line'!$A$2:$A$107,A11,'2. Check each line'!$R$2:$R$107,"Same part, price just varies")
A12: C11 | B12: F/B LOWER GRILLE | C12: Toyota | D12: Prices are scattered widely around the typical price | E12: 4 | F12: 65 | G12: 75 | H12: 220 | I12: 3.4 | J12: 3 | K12: 1 | L12: F/B LOWER GRILLE F/B LOWER CENTRE GRILLE | M12: 2025-09-17-AIG Asia Pacific Insurance Pte. Ltd.-TOYOTA-21.PDF 2025-11-24-Tokio Marine Insurance Singapore Ltd-TOYOTA-81.PDF 2026-02-12-AIG Asia Pacific Insurance Pte. Ltd.-TOYOTA-178.PDF 2025-10-27-AIG Asia Pacific Insurance Pte. Ltd.-TOYOTA-60.PDF | N12: =COUNTIFS('2. Check each line'!$A$2:$A$107,A12,'2. Check each line'!$R$2:$R$107,"<>")&" of "&COUNTIF('2. Check each line'!$A$2:$A$107,A12) | O12: =COUNTIFS('2. Check each line'!$A$2:$A$107,A12,'2. Check each line'!$R$2:$R$107,"Same part, price just varies")
A13: C12 | B13: BRACKET- FASCIA FRT CTR TO FDR LH | C13: Tesla | D13: Comparison group: prices fairly close together, so it should be the same part | E13: 8 | F13: 7.1 | G13: 11.28 | H13: 11.28 | I13: 1.6 | J13: 3 | K13: 2 | L13: BRACKET- FASCIA FRT CTR TO FDR LH BRACKET- FASCIA FRT CTR TO FDR RH BRACKET - FASCIA SIDE TO FDR LH BRACKET-FASCIA FRT CTR TO FDR LH | M13: 2026-02-09-Allianz Insurance Singapore Pte. Ltd.-TESLA-155.PDF 2026-02-09-Allianz Insurance Singapore Pte. Ltd.-TESLA-158.JPG 2026-02-09-Allianz Insurance Singapore Pte. Ltd.-TESLA-173.JPG 2025-12-02-Allianz Insurance Singapore Pte. Ltd.-TESLA-94.PDF 2025-12-02-Allianz Insurance Singapore Pte. Ltd.-TESLA-95.PDF 2026-02-09-Allianz Insurance Singapore Pte. Ltd.-TESLA-156.PDF | N13: =COUNTIFS('2. Check each line'!$A$2:$A$107,A13,'2. Check each line'!$R$2:$R$107,"<>")&" of "&COUNTIF('2. Check each line'!$A$2:$A$107,A13) | O13: =COUNTIFS('2. Check each line'!$A$2:$A$107,A13,'2. Check each line'!$R$2:$R$107,"Same part, price just varies")
... A17: C16 | B17: Hood | C17: Mercedes-Benz | D17: Comparison group: prices fairly close together, so it should be the same part | E17: 4 | F17: 1150 | G17: 1274.5 | H17: 1480 | I17: 1.3 | J17: 3 | K17: 2 | L17: Hood HOOD | M17: 2025-08-17-Allianz Insurance Singapore Pte. Ltd.-MERCEDES-BENZ-6.JPG Min Ghee Auto Pte Ltd 8122844 (no scan) 2026-01-05-Allianz Insurance Singapore Pte. Ltd.-MERCEDES-BENZ-132.PDF 2025-10-17-AIG Asia Pacific Insurance Pte. Ltd.-MERCEDES-BENZ-55.PDF | N17: =COUNTIFS('2. Check each line'!$A$2:$A$107,A17,'2. Check each line'!$R$2:$R$107,"<>")&" of "&COUNTIF('2. Check each line'!$A$2:$A$107,A17) | O17: =COUNTIFS('2. Check each line'!$A$2:$A$107,A17,'2. Check each line'!$R$2:$R$107,"Same part, price just varies")

Sheet 4. Results
A1: Progress
A2: Lines with a reason picked | B2: =COUNTA('2. Check each line'!$R$2:$R$107)&" of 106"
A3: Groups with a verdict | B3: =COUNTA('3. Price groups'!$P$2:$P$17)&" of 16"
A5: Why do the prices differ? (one row per reason)
A6: Reason | B6: Wide-range groups | C6: Share | D6: Comparison groups | E6: What it means
A7: Same part, price just varies | B7: =COUNTIFS('2. Check each line'!$C$2:$C$107,"",'2. Check each line'!$R$2:$R$107,"Same part, price just varies") | C7: =IFERROR(B7/COUNTIFS('2. Check each line'!$C$2:$C$107,"",'2. Check each line'!$R$2:$R$107,"<>"),"") | D7: =COUNTIFS('2. Check each line'!$C$2:$C$107,"Yes",'2. Check each line'!$R$2:$R$107,"Same part, price just varies") | E7: It really is the same part. The price difference is genuine (different supplier, date or deal).
A8: Smaller piece of the part | B8: =COUNTIFS('2. Check each line'!$C$2:$C$107,"",'2. Check each line'!$R$2:$R$107,"Smaller piece of the part") | C8: =IFERROR(B8/COUNTIFS('2. Check each line'!$C$2:$C$107,"",'2. Check each line'!$R$2:$R$107,"<>"),"") | D8: =COUNTIFS('2. Check each line'!$C$2:$C$107,"Yes",'2. Check each line'!$R$2:$R$107,"Smaller piece of the part") | E8: A clip, bracket, cover or other small piece, grouped with the full part (e.g. a S$5 bumper clip next to a S$600 bumper).
A9: Same name, different car | B9: =COUNTIFS('2. Check each line'!$C$2:$C$107,"",'2. Check each line'!$R$2:$R$107,"Same name, different car") | C9: =IFERROR(B9/COUNTIFS('2. Check each line'!$C$2:$C$107,"",'2. Check each line'!$R$2:$R$107,"<>"),"") | D9: =COUNTIFS('2. Check each line'!$C$2:$C$107,"Yes",'2. Check each line'!$R$2:$R$107,"Same name, different car") | E9: Same kind of part, but made for a different car model, so not interchangeable.
A10: Different position (front/rear etc.) | B10: =COUNTIFS('2. Check each line'!$C$2:$C$107,"",'2. Check each line'!$R$2:$R$107,"Different position (front/rear etc.)") | C10: =IFERROR(B10/COUNTIFS('2. Check each line'!$C$2:$C$107,"",'2. Check each line'!$R$2:$R$107,"<>"),"") | D10: =COUNTIFS('2. Check each line'!$C$2:$C$107,"Yes",'2. Check each line'!$R$2:$R$107,"Different position (front/rear etc.)") | E10: Front vs rear, upper vs lower, or inner vs outer.
A11: Different quality (genuine/copy/used) | B11: =COUNTIFS('2. Check each line'!$C$2:$C$107,"",'2. Check each line'!$R$2:$R$107,"Different quality (genuine/copy/used)") | C11: =IFERROR(B11/COUNTIFS('2. Check each line'!$C$2:$C$107,"",'2. Check each line'!$R$2:$R$107,"<>"),"") | D11: =COUNTIFS('2. Check each line'!$C$2:$C$107,"Yes",'2. Check each line'!$R$2:$R$107,"Different quality (genuine/copy/used)") | E11: Genuine maker's part vs a copy (aftermarket) or a used/reconditioned one.
A12: Priced as a pair or set | B12: =COUNTIFS('2. Check each line'!$C$2:$C$107,"",'2. Check each line'!$R$2:$R$107,"Priced as a pair or set") | C12: =IFERROR(B12/COUNTIFS('2. Check each line'!$C$2:$C$107,"",'2. Check each line'!$R$2:$R$107,"<>"),"") | D12: =COUNTIFS('2. Check each line'!$C$2:$C$107,"Yes",'2. Check each line'!$R$2:$R$107,"Priced as a pair or set") | E12: The line charges for two (left and right) or a kit, not one piece.
A13: Reading mistake on our record | B13: =COUNTIFS('2. Check each line'!$C$2:$C$107,"",'2. Check each line'!$R$2:$R$107,"Reading mistake on our record") | C13: =IFERROR(B13/COUNTIFS('2. Check each line'!$C$2:$C$107,"",'2. Check each line'!$R$2:$R$107,"<>"),"") | D13: =COUNTIFS('2. Check each line'!$C$2:$C$107,"Yes",'2. Check each line'!$R$2:$R$107,"Reading mistake on our record") | E13: Our record has the wrong part number or price compared with the bill itself.
A14: Can't tell | B14: =COUNTIFS('2. Check each line'!$C$2:$C$107,"",'2. Check each line'!$R$2:$R$107,"Can't tell") | C14: =IFERROR(B14/COUNTIFS('2. Check each line'!$C$2:$C$107,"",'2. Check each line'!$R$2:$R$107,"<>"),"") | D14: =COUNTIFS('2. Check each line'!$C$2:$C$107,"Yes",'2. Check each line'!$R$2:$R$107,"Can't tell") | E14: Not enough information on the bill or online to decide.
A15: Total answered | B15: =SUM(B7:B14) | D15: =SUM(D7:D14)
A17: The answer
A18: Lines that are genuinely the same part | B18: =IFERROR(B7/COUNTIFS('2. Check each line'!$C$2:$C$107,"",'2. Check each line'!$R$2:$R$107,"<>"),0) | E18: Out of the lines answered in the wide-range groups.
A19: Lines that are a different part or for a different car | B19: =IFERROR(SUM(B8:B12)/COUNTIFS('2. Check each line'!$C$2:$C$107,"",'2. Check each line'!$R$2:$R$107,"<>"),0) | E19: Smaller piece, different car, different position, different quality, or pair/set.
A20: Lines with a reading mistake on our record | B20: =IFERROR(B13/COUNTIFS('2. Check each line'!$C$2:$C$107,"",'2. Check each line'!$R$2:$R$107,"<>"),0) | E20: These should be corrected in the reference whatever the conclusion.
A21: In plain words | B21: =IF(COUNTA('2. Check each line'!$R$2:$R$107)<85,"Finish most of sheet 2 first.",IF(IFERROR(B7/COUNTIFS('2. Check each line'!$C$2:$C$107,"",'2. Check each line'!$R$2:$R$107,"<>"),0)>=0.7,"Mostly real price differences: the wide ranges reflect the market, and the typical price can be used as it is.",IF(IFERROR(SUM(B8:B12)/COUNTIFS('2. Check each line'!$C$2:$C$107,"",'2. Check each line'!$R$2:$R$107,"<>"),0)>=0.5,"Mostly different parts grouped together: the typical price is misleading for these groups. Fix how parts are grouped (for example, group by exact part number) rather than changing the statistics.","A mix of both: some ranges are real, others come from different parts being grouped together. Review the groups one by one on sheet 3.")))
A22: Comparison groups check | B22: =IF(D15=0,"Not answered yet.",IF(D7/D15>=0.7,"OK: the comparison groups mostly came back as the same part, as expected.","Warning: even the comparison groups came back mostly as different parts. Either the checking is too strict, or the grouping problem affects every group."))

Sheet 5. Bills
A1: Supplier | B1: Bill number | C1: Bill date | D1: Bill file name | E1: Open the bill | F1: Groups it appears in | G1: Lines in this check
A2: HE XING AUTO PARTS PTE LTD | B2: DLI9281439 | C2: 26/04/2025 | D2: 2025-05-20-Allianz Insurance Singapore Pte. Ltd.-TOYOTA-1.PDF | E2: Open | F2: C15 | G2: 1
A3: MIN GHEE AUTO PTE LTD | B3: 8397352 | C3: 03/07/2025 | D3: 2025-08-17-Allianz Insurance Singapore Pte. Ltd.-MERCEDES-BENZ-6.JPG | E3: Open | F3: C01, C09, C14, C16 | G3: 8
A4: FORTUNA AUTOMOTIVE PTE LTD | B4: CL2508534 | C4: 27/08/2025 | D4: 2025-09-17-AIG Asia Pacific Insurance Pte. Ltd.-TOYOTA-21.PDF | E4: Open | F4: C02, C11 | G4: 3
A5: JAE AUTO PTE LTD | B5: AR202509-09589 | C5: 22/09/2025 | D5: 2025-09-26-EQ Insurance Company Ltd-TOYOTA-26.PDF | E5: Open | F5: C07 | G5: 1
A6: JAE AUTO PTE LTD | B6: AR202509-09533 | C6: 22/09/2025 | D6: 2025-09-26-EQ Insurance Company Ltd-TOYOTA-27.PDF | E6: Open | F6: C13 | G6: 1
A7: JAE AUTO PTE LTD | B7: AR202509-09989 | C7: 23/09/2025 | D7: 2025-09-26-EQ Insurance Company Ltd-TOYOTA-29.PDF | E7: Open | F7: C07 | G7: 1
A8: Precision Auto Parts Supplies Pte Ltd | B8: INV-0463 | C8: 29/09/2025 | D8: 2025-10-08-AIG Asia Pacific Insurance Pte. Ltd.-TOYOTA-45.PDF | E8: Open | F8: C02 | G8: 2
A9: MIN GHEE AUTO PTE. LTD. | B9: 8407516 | C9: 01/10/2025 | D9: 2025-10-15-AIG Asia Pacific Insurance Pte. Ltd.-MERCEDES-BENZ-49.PDF | E9: Open | F9: C01 | G9: 1
A10: MIN GHEE AUTO PTE LTD | B10: 8405253 | C10: 11/09/2025 | D10: 2025-10-17-AIG Asia Pacific Insurance Pte. Ltd.-MERCEDES-BENZ-55.PDF | E10: Open | F10: C01, C04, C16 | G10: 3
A11: SURPASS AUTO PARTS SUPPLIES PTE LTD | B11: 25100058 | C11: 06/10/2025 | D11: 2025-10-21-AIG Asia Pacific Insurance Pte. Ltd.-MERCEDES-BENZ-57.PDF | E11: Open | F11: C14 | G11: 1
A12: HE XING AUTO PARTS PTE LTD | B12: DLI9281716 | C12: 10/05/2025 | D12: 2025-10-21-HL Assurance Pte Ltd-TOYOTA-58.PDF | E12: Open | F12: C02, C06 | G12: 2
A13: FORTUNA AUTOMOTIVE PTE LTD | B13: CL2510229 | C13: 15/10/2025 | D13: 2025-10-27-AIG Asia Pacific Insurance Pte. Ltd.-TOYOTA-60.PDF | E13: Open | F13: C02, C11 | G13: 2
... A37: Tesla Motors Singapore Private Limited | B37: 2040R0000004188 | C37: 31/07/2025 | D37: 2026-02-09-Allianz Insurance Singapore Pte. Ltd.-TESLA-156.PDF | E37: Open | F37: C12 | G37: 1
A38: Tesla | B38: EPC-5140005-1 | D38: 2026-02-09-Allianz Insurance Singapore Pte. Ltd.-TESLA-158.JPG | E38: Open | F38: C12 | G38: 2
A39: Tesla Motors Singapore Private Limited | B39: 2040R0000004919 | C39: 20/11/2025 | D39: 2026-02-09-Allianz Insurance Singapore Pte. Ltd.-TESLA-169.PDF | E39: Open | F39: C03 | G39: 2
A40: Tesla | C40: 28/11/2025 | D40: 2026-02-09-Allianz Insurance Singapore Pte. Ltd.-TESLA-173.JPG | E40: Open | F40: C03, C12 | G40: 5
A41: FORTUNA AUTOMOTIVE PTE LTD | B41: CL2508246 | C41: 13/08/2025 | D41: 2026-02-12-AIG Asia Pacific Insurance Pte. Ltd.-TOYOTA-178.PDF | E41: Open | F41: C11, C13 | G41: 2
A42: HE XING AUTO PARTS PTE LTD | B42: DLI9283883 | C42: 22/08/2025 | D42: 2026-02-23-Allianz Insurance Singapore Pte. Ltd.-TOYOTA-179.PDF | E42: Open | F42: C02 | G42: 1
A43: JAE AUTO PTE LTD | B43: AR202601-05752 | C43: 14/01/2026 | D43: 2026-02-25-ECICS Limited-TOYOTA-181.PDF | E43: Open | F43: C06, C07, C10 | G43: 4
A44: Min Ghee Auto Pte Ltd | B44: 8122844 | C44: 10/04/2018 | D44: No scanned copy on this computer (older bill, added from a spreadsheet) | E44: – | F44: C01, C16 | G44: 2
A45: Min Ghee Auto Pte Ltd | B45: 8123192 | C45: 10/08/2018 | D45: No scanned copy on this computer (older bill, added from a spreadsheet) | E45: – | F45: C04 | G45: 1
A46: Jae Auto Pte Ltd | B46: AR201805-00837 | C46: 05/02/2018 | D46: No scanned copy on this computer (older bill, added from a spreadsheet) | E46: – | F46: C05 | G46: 1
A47: Jae Auto Pte Ltd | B47: AR201805-02365 | C47: 05/05/2018 | D47: No scanned copy on this computer (older bill, added from a spreadsheet) | E47: – | F47: C05 | G47: 1
A48: Jae Auto Pte Ltd | B48: AR201805-03001 | C48: 05/07/2018 | D48: No scanned copy on this computer (older bill, added from a spreadsheet) | E48: – | F48: C05 | G48: 1
A49: Jae Auto Pte Ltd | B49: AR201804-1417 | C49: 25/04/2018 | D49: No scanned copy on this computer (older bill, added from a spreadsheet) | E49: – | F49: C05 | G49: 2
A50: Jae Auto Pte Ltd | B50: AR201806-15561 | C50: 29/06/2018 | D50: No scanned copy on this computer (older bill, added from a spreadsheet) | E50: – | F50: C10 | G50: 1
